Workbook

Sheet BASE BI
A1: ticket_id | B1: protocolo | C1: titulo | D1: UsuarioDesignado | E1: segmento_cliente | F1: numplan | G1: idservico | H1: valorservico | I1: produto | J1: cliente_id | K1: Cliente | L1: CNPJ | M1: data_abertura | N1: data_fechamento | O1: substatus | P1: dep_atual | Q1: Canal_Abertura | R1: Tipo_Encerramento | S1: Causa_Raiz | T1: parceiro | U1: ult_OS | V1: os_agrupada | W1: os_concluida_agrupada | X1: ufservico | Y1: cidadeservico | Z1: bdeskprotocol | AA1: aging_ccs | AB1: tempo_total | AC1: tempo_cliente | AD1: tempo_giga | AE1: tempo_suporte_total | AF1: tempo_noc | AG1: tempo_ccs | AH1: tempo_b2b | AI1: tempoccs_campo | AJ1: tempo_escritorio | AK1: tempo_swap | AL1: DataAtivacao | AM1: intervalo_ativacao | AN1: classificacao_ifi | AO1: designator | AP1: nova_regional | AQ1: cluster | AR1: gerente | AS1: sla_ticket | AT1: semana | AU1: ano | AV1: mes | AW1: cluster_calc | AX1: dentro_8h | AY1: outlier_24h | BT1: cluster_calc | BU1: dentro_8h | BV1: outlier_24h
A2: 5738809 | B2: 30122025-78733 | C2: SERVIS ELETRONICA DEFENSE LTDA MA GRUPO SERVIS | INDISPONIBILIDADE | SLS/L2L/218497/771 | D2: Glen Serafim | E2: Corporativo | F2: 768 | G2: 293293 | H2: 471.74 | I2: LINK DE DADOS | J2: 218497 | K2: SERVIS ELETRONICA DEFENSE LTDA MA GRUPO SERVIS | L2: 04.196.136/0003-31 | M2: 46021.768 | N2: 46023.644 | O2: PENDENTE VALIDAÇÃO | P2: CMO - Reparo | R2: Rompimento de Fibra | U2: 165937 | V2: 165937 | W2: 165937 | X2: MA | Y2: SAO LUIS | AA2: Entre 4h e 8h | AB2: 44.966666 | AC2: 39.433333 | AD2: 5.533333 | AE2: 0.25 | AF2: 0 | AG2: 5.283333 | AH2: 5.283333 | AI2: 5.183333 | AJ2: 0.1 | AK2: 0 | AL2: 45191.77 | AM2: 829 | AN2: Maior que 15d pós ativação | AO2: SLS/L2L/218497/768 | AP2: MA, PA, PI E AP | AQ2: C.32 - Maranhão | AR2: Wellington Marcio | AT2: S01 | AU2: 2026 | AV2: 1 | AW2: MA CAP | AX2: 1 | AY2: 0 | BT2: MA CAP | BU2: 1 | BV2: 0
A3: 5739621 | B3: 31122025-59475 | C3: Queda de link primário | D3: Stephanie Aparecida Arthur | E3: Corporativo | F3: 65 | G3: 290179 | H3: 300 | I3: LINK DE DADOS | J3: 13955 | K3: PFM COMERCIAL LTDA - CASA FREITAS | L3: 01.740.627/0001-41 | M3: 46022.355 | N3: 46024.443 | O3: PENDENTE VALIDAÇÃO | P3: CMO - Reparo | Q3: Portal do Cliente | R3: Rompimento de Fibra | U3: 165821 | V3: 165821 | W3: 165821 | X3: PI | Y3: PARNAIBA | AA3: Até 4h | AB3: 50.033335 | AC3: 44.783333 | AD3: 5.250002 | AE3: 2.066668 | AF3: 0 | AG3: 3.183334 | AH3: 3.183334 | AI3: 2.783334 | AJ3: 0.4 | AK3: 0 | AL3: 45026 | AM3: 996 | AN3: Maior que 15d pós ativação | AO3: PNA/L2L/13955/65 | AP3: MA, PA, PI E AP | AQ3: C.31 - Piaui | AR3: Wellington Marcio | AT3: S01 | AU3: 2026 | AV3: 1 | AW3: PI INT | AX3: 1 | AY3: 0 | BT3: PI INT | BU3: 1 | BV3: 0
A4: 5737945 | B4: 30122025-94754 | C4: Atendimento para: SEMOSP - SEDE - SLS-216233-00033 | D4: Stephanie Aparecida Arthur | E4: Público | F4: 33 | G4: 275253 | H4: 740.61 | I4: LINK DE DADOS | J4: 216233 | K4: MUNICIPIO DE SAO LUIS SEMIT | L4: 06.307.102/0001-30 | M4: 46021.585 | N4: 46024.448 | O4: PENDENTE VALIDAÇÃO | P4: CMO - Reparo | Q4: Email | R4: Rompimento de Fibra | U4: 165835 | V4: 165835 | W4: 165835 | X4: MA | Y4: SAO LUIS | Z4: 521037 - Manutenção corretiva || OLT br.ma.sls.chf.gp.02 || SLOT 1; PON 3 a 9 || 67 afetados | AA4: Entre 4h e 8h | AB4: 68.65 | AC4: 41.583333 | AD4: 27.066667 | AE4: 21.816667 | AF4: 21.166667 | AG4: 5.25 | AH4: 26.416667 | AI4: 5.05 | AJ4: 0.2 | AK4: 0 | AL4: 44838 | AM4: 1183 | AN4: Maior que 15d pós ativação | AO4: SLS/L2L/216233/33 | AP4: MA, PA, PI E AP | AQ4: C.32 - Maranhão | AR4: Wellington Marcio | AT4: S01 | AU4: 2026 | AV4: 1 | AW4: MA CAP | AX4: 1 | AY4: 0 | BT4: MA CAP | BU4: 1 | BV4: 0
A5: 5738939 | B5: 30122025-29109 | C5: Atendimento para: UEB ENS FUND NEWTON NEVES - SLS-216233-00288 | D5: Stephanie Aparecida Arthur | E5: Público | F5: 288 | G5: 286441 | H5: 364.96 | I5: LINK DE DADOS | J5: 218787 | K5: MUNICIPIO DE SAO LUIS SEMED | L5: 06.307.102/0002-11 | M5: 46021.85 | N5: 46024.467 | O5: PENDENTE VALIDAÇÃO | P5: CMO - Reparo | Q5: E-Care | R5: Normalizado Sem Intervenção | U5: 165827 | V5: 165827 | X5: MA | Y5: SAO LUIS | AA5: Entre 8h e 12h | AB5: 62.733333 | AC5: 52.983333 | AD5: 9.75 | AE5: 0.233333 | AF5: 0 | AG5: 9.516667 | AH5: 9.516667 | AI5: 9.4 | AJ5: 0.116667 | AK5: 0 | AL5: 44896 | AM5: 1125 | AN5: Maior que 15d pós ativação | AO5: SLS/L2L/218787/288 | AP5: MA, PA, PI E AP | AQ5: C.32 - Maranhão | AR5: Wellington Marcio | AT5: S01 | AU5: 2026 | AV5: 1 | AW5: MA CAP | AX5: 0 | AY5: 0 | BT5: MA CAP | BU5: 0 | BV5: 0
A6: 5734511 | B6: 29122025-60212 | C6: ABERTURA DE CHAMADO/202540973903/GRUPO CASAS BAHIA S A | D6: Stephanie Aparecida Arthur | E6: Operadoras | F6: 122 | G6: 324995 | H6: 650 | I6: LINK DE DADOS | J6: 225215 | K6: VOGEL SOLUCOES EM TELECOMUNICACOES E INFORMATICA S A ALGAR TELECOM | L6: 05.872.814/0013-73 | M6: 46020.661 | N6: 46024.469 | O6: PENDENTE VALIDAÇÃO | P6: CMO - Reparo | Q6: Email | R6: Rompimento de Fibra | U6: 165109 | V6: 164907, 165109 | W6: 165109 | X6: PI | Y6: PICOS | AA6: Entre 4h e 8h | AB6: 91.35 | AC6: 85.616666 | AD6: 5.733334 | AE6: 0.566667 | AF6: 0 | AG6: 5.166667 | AH6: 5.166667 | AI6: 4.816667 | AJ6: 0.35 | AK6: 0 | AL6: 45573.576 | AM6: 447 | AN6: Maior que 15d pós ativação | AO6: PCZ/L2L/225215/122 | AP6: MA, PA, PI E AP | AQ6: C.31 - Piaui | AR6: Wellington Marcio | AT6: S01 | AU6: 2026 | AV6: 1 | AW6: PI INT | AX6: 1 | AY6: 0 | BT6: PI INT | BU6: 1 | BV6: 0
A7: 5720611 | B7: 25122025-57218 | C7: ABERTURA DE CHAMADO - 04.2001 - INC8427715 - MOB TELECOM | D7: Stephanie Aparecida Arthur | E7: Corporativo | F7: 1 | G7: 251091 | H7: 1749.9 | I7: LINK DEDICADO DE INTERNET | J7: 203451 | K7: SICREDI NORTE COOP DE CREDITO UNIDADE DE ATENDIMENTO GENERALISSIMO | L7: 83.315.408/0003-41 | M7: 46016.022 | N7: 46024.474 | O7: PENDENTE VALIDAÇÃO | P7: CMO - Reparo | Q7: Email | R7: Rompimento de Fibra | U7: 165267 | V7: 165267 | W7: 165267 | X7: PA | Y7: BELEM | AA7: Entre 8h e 12h | AB7: 202.81667 | AC7: 175 | AD7: 27.816668 | AE7: 17.033334 | AF7: 0 | AG7: 10.783334 | AH7: 10.783334 | AI7: 10.733334 | AJ7: 0.05 | AK7: 0 | AL7: 44638 | AM7: 1378 | AN7: Maior que 15d pós ativação | AO7: BLM/IPD/203451/1 | AP7: MA, PA, PI E AP | AQ7: C.28 - Norte | AR7: Wellington Marcio | AT7: S01 | AU7: 2026 | AV7: 1 | AW7: PA CAP | AX7: 0 | AY7: 0 | BT7: PA CAP | BU7: 0 | BV7: 0
A8: 5738195 | B8: 30122025-33861 | C8: ARION SERVICOS DE TELECOMUNICACOES LTDA | Indisponibilidade | Contrato 6453266 | D8: Vanessa Alves Ferreira | E8: Provedores | F8: 1 | G8: 335653 | H8: 79.9 | I8: BANDA LARGA WIFI 5 + IP FIXO FS | J8: 201863 | K8: ARION SERVICOS DE TELECOMUNICACOES LTDA ARION SERVICES | L8: 20.059.578/0001-20 | M8: 46021.618 | N8: 46024.477 | O8: PENDENTE VALIDAÇÃO | P8: CMO - Reparo | Q8: Chat | R8: Ajuste de Atenuação | U8: 166051 | V8: 165539, 166051 | W8: 166051 | X8: MA | Y8: PRESIDENTE DUTRA | AA8: Até 4h | AB8: 68.533334 | AC8: 65.066666 | AD8: 3.466668 | AE8: 0.466667 | AF8: 0 | AG8: 3.000001 | AH8: 3.000001 | AI8: 2.716667 | AJ8: 0.283334 | AK8: 0 | AN8: Sem data de ativação | AO8: PDU/FBR/201863/1 | AP8: MA, PA, PI E AP | AQ8: C.32 - Maranhão | AR8: Wellington Marcio | AT8: S01 | AU8: 2026 | AV8: 1 | AW8: MA INT | AX8: 1 | AY8: 0 | BT8: MA INT | BU8: 1 | BV8: 0
A9: 5739173 | B9: 31122025-47557 | C9: RCR LOCACAO LTDA R C R LOCACAO LTDA | INDISPONIBILIDADE | SLS/IPD/226111/1 | D9: Rennan Lima da Penha | E9: Corporativo | F9: 1 | G9: 333399 | H9: 600 | I9: IP CONNECT Metro | J9: 226111 | K9: RCR LOCACAO LTDA R C R LOCACAO LTDA | L9: 01.203.383/0006-72 | M9: 46022.02 | N9: 46024.493 | O9: PENDENTE VALIDAÇÃO | P9: CMO - Reparo | Q9: Chat | R9: Falha Elétrica Cliente | U9: 165983 | V9: 165639, 165983 | W9: 165983 | X9: MA | Y9: SAO LUIS | AA9: Entre 4h e 8h | AB9: 59.233335 | AC9: 51.116667 | AD9: 8.116668 | AE9: 0.166667 | AF9: 0 | AG9: 7.950001 | AH9: 7.950001 | AI9: 7.733334 | AJ9: 0.216667 | AK9: 0 | AL9: 45771.443 | AM9: 250 | AN9: Maior que 15d pós ativação | AO9: SLS/IPD/226111/1 | AP9: MA, PA, PI E AP | AQ9: C.32 - Maranhão | AR9: Wellington Marcio | AT9: S01 | AU9: 2026 | AV9: 1 | AW9: MA CAP | AX9: 1 | AY9: 0 | BT9: MA CAP | BU9: 1 | BV9: 0
A10: 5738689 | B10: 30122025-39784 | C10: Atendimento para: UEB PROF ELPIDIO HERMES DE CARVALHO - POLO | D10: Laura Beatriz de Sibia Santos | E10: Público | F10: 253 | G10: 286349 | H10: 364.96 | I10: LINK DE DADOS | J10: 216233 | K10: MUNICIPIO DE SAO LUIS SEMIT | L10: 06.307.102/0001-30 | M10: 46021.732 | N10: 46024.594 | O10: PENDENTE VALIDAÇÃO | P10: CMO - Reparo | Q10: Email | R10: Ajuste de Atenuação | U10: 165645 | V10: 165645 | W10: 165645 | X10: MA | Y10: SAO LUIS | AA10: Entre 4h e 8h | AB10: 68.616668 | AC10: 62.166667 | AD10: 6.450001 | AE10: 0.483334 | AF10: 0 | AG10: 5.966667 | AH10: 5.966667 | AI10: 5.25 | AJ10: 0.716667 | AK10: 0 | AL10: 44893 | AM10: 1128 | AN10: Maior que 15d pós ativação | AO10: SLS/L2L/218787/253 | AP10: MA, PA, PI E AP | AQ10: C.32 - Maranhão | AR10: Wellington Marcio | AT10: S01 | AU10: 2026 | AV10: 1 | AW10: MA CAP | AX10: 1 | AY10: 0 | BT10: MA CAP | BU10: 1 | BV10: 0
A11: 5734265 | B11: 29122025-37162 | C11: Atendimento para: UEB MARIA AMELIA PROFETA - SLS-216233-00266 | D11: Vinicius da Silva Dos Santos | E11: Público | F11: 266 | G11: 286377 | H11: 364.96 | I11: LINK DE DADOS | J11: 218787 | K11: MUNICIPIO DE SAO LUIS SEMED | L11: 06.307.102/0002-11 | M11: 46020.612 | N11: 46024.692 | O11: PENDENTE VALIDAÇÃO | P11: CMO - Reparo | Q11: E-Care | R11: Configuração | U11: 165975 | V11: 165975, 165989 | W11: 165975 | X11: MA | Y11: SAO LUIS | AA11: Entre 4h e 8h | AB11: 97.716668 | AC11: 85.633333 | AD11: 12.083335 | AE11: 5.000001 | AF11: 0 | AG11: 7.083334 | AH11: 7.083334 | AI11: 7.016667 | AJ11: 0.066667 | AK11: 0 | AL11: 44890 | AM11: 1130 | AN11: Maior que 15d pós ativação | AO11: SLS/L2L/218787/266 | AP11: MA, PA, PI E AP | AQ11: C.32 - Maranhão | AR11: Wellington Marcio | AT11: S01 | AU11: 2026 | AV11: 1 | AW11: MA CAP | AX11: 1 | AY11: 0 | BT11: MA CAP | BU11: 1 | BV11: 0
A12: 5739873 | B12: 31122025-56127 | C12: 3273 SAA AG. AV. GUAJAJARAS LINCK DO NOVO CONTRATO | D12: INGRID DA SILVA CALIXTO SANTANA | E12: Operadoras | F12: 638 | G12: 342937 | H12: 225 | I12: BANDA LARGA WIFI 5 + IP FIXO | J12: 48887 | K12: BRISANET SERVICOS DE TELECOMUNICACOES LTDA BRISANET SERVICOS DE TELECOMUNICACOES LTDA | L12: 04.601.397/0001-28 | M12: 46022.42 | N12: 46024.75 | O12: PENDENTE VALIDAÇÃO | P12: CMO - Reparo | Q12: Portal do Cliente | R12: Rompimento de Fibra | U12: 165985 | V12: 165805, 165985 | W12: 165985 | X12: MA | Y12: SAO LUIS | AA12: Entre 8h e 12h | AB12: 55.816667 | AC12: 47.45 | AD12: 8.366667 | AE12: 0.25 | AF12: 0 | AG12: 8.116667 | AH12: 8.116667 | AI12: 7.516667 | AJ12: 0.6 | AK12: 0 | AL12: 45855 | AM12: 167 | AN12: Maior que 15d pós ativação | AO12: SLS/FBR/48887/638 | AP12: MA, PA, PI E AP | AQ12: C.32 - Maranhão | AR12: Wellington Marcio | AT12: S01 | AU12: 2026 | AV12: 1 | AW12: MA CAP | AX12: 0 | AY12: 0 | BT12: MA CAP | BU12: 0 | BV12: 0
A13: 5741385 | B13: 01012026-28447 | C13: Atendimento para: UEB OLINDA DESTERRO INFANTIL - SLS-216233-00166 | D13: Vinicius da Silva Dos Santos | E13: Público | F13: 166 | G13: 285815 | H13: 364.95 | I13: LINK DE DADOS | J13: 218787 | K13: MUNICIPIO DE SAO LUIS SEMED | L13: 06.307.102/0002-11 | M13: 46023.487 | N13: 46024.775 | O13: PENDENTE VALIDAÇÃO | P13: CMO - Reparo | Q13: Email | R13: Rompimento de Fibra | U13: 165987 | V13: 165987 | W13: 165987 | X13: MA | Y13: SAO LUIS | AA13: Até 4h | AB13: 30.833333 | AC13: 26.866666 | AD13: 3.966667 | AE13: 0.133334 | AF13: 0 | AG13: 3.833333 | AH13: 3.833333 | AI13: 3.733333 | AJ13: 0.1 | AK13: 0 | AL13: 44875 | AM13: 1148 | AN13: Maior que 15d pós ativação | AO13: SLS/L2L/218787/166 | AP13: MA, PA, PI E AP | AQ13: C.32 - Maranhão | AR13: Wellington Marcio | AT13: S01 | AU13: 2026 | AV13: 1 | AW13: MA CAP | AX13: 1 | AY13: 0 | BT13: MA CAP | BU13: 1 | BV13: 0
A14: 5743651 | B14: 03012026-57179 | C14: Indisponivel - São Luis | INOVANET | SLS/L2L/133341/12 | D14: Stephanie Aparecida Arthur | E14: Provedores | F14: 12 | G14: 342751 | H14: 250 | I14: L2L Metro | J14: 133341 | K14: INOVANET EMPREENDIMENTOS LTDA. INOVANET | L14: 21.278.402/0001-22 | M14: 46025.358 | N14: 46025.477 | O14: PENDENTE VALIDAÇÃO | P14: CMO - Reparo | Q14: Chat | R14: Normalizado Sem Intervenção | U14: 166347 | V14: 166347 | X14: MA | Y14: SAO LUIS | AA14: Até 4h | AB14: 2.8 | AC14: 0.05 | AD14: 2.75 | AE14: 0.55 | AF14: 0 | AG14: 2.2 | AH14: 2.2 | AI14: 1.15 | AJ14: 1.05 | AK14: 0 | AL14: 45982.485 | AM14: 42 | AN14: Maior que 15d pós ativação | AO14: SLS/L2L/133341/12 | AP14: MA, PA, PI E AP | AQ14: C.32 - Maranhão | AR14: Wellington Marcio | AT14: S01 | AU14: 2026 | AV14: 1 | AW14: MA CAP | AX14: 1 | AY14: 0 | BT14: MA CAP | BU14: 1 | BV14: 0
A15: 5743253 | B15: 02012026-58558 | C15: SERVIS ELETRONICA DEFENSE | INDISPONIBILIDADE | SLS/L2L/218497/768 | D15: ANA PAULA DA SILVA SANTOS | E15: Corporativo | F15: 768 | G15: 293293 | H15: 471.74 | I15: LINK DE DADOS | J15: 218497 | K15: SERVIS ELETRONICA DEFENSE LTDA MA GRUPO SERVIS | L15: 04.196.136/0003-31 | M15: 46024.886 | N15: 46025.557 | O15: PENDENTE VALIDAÇÃO | P15: CMO - Reparo | Q15: Chat | R15: Rompimento de Fibra | U15: 166257 | V15: 166257 | W15: 166257 | X15: MA | Y15: SAO LUIS | AA15: Entre 4h e 8h | AB15: 16.033334 | AC15: 11.266667 | AD15: 4.766667 | AE15: 0.05 | AF15: 0 | AG15: 4.716667 | AH15: 4.716667 | AI15: 3.766667 | AJ15: 0.95 | AK15: 0 | AL15: 45191.77 | AM15: 833 | AN15: Maior que 15d pós ativação | AO15: SLS/L2L/218497/768 | AP15: MA, PA, PI E AP | AQ15: C.32 - Maranhão | AR15: Wellington Marcio | AT15: S01 | AU15: 2026 | AV15: 1 | AW15: MA CAP | AX15: 1 | AY15: 0 | BT15: MA CAP | BU15: 1 | BV15: 0
A16: 5743129 | B16: 02012026-98049 | C16: FBR DIGITAL SA FBR DIGITAL | INDISPONIBILIDADE | ZED/FBR/74371/9 | D16: INGRID DA SILVA CALIXTO SANTANA | E16: Corporativo | F16: 9 | G16: 335547 | H16: 199.8 | I16: BANDA LARGA WIFI 5 + IP FIXO | J16: 74371 | K16: FBR DIGITAL SA FBR DIGITAL | L16: 12.868.281/0001-88 | M16: 46024.787 | N16: 46026.387 | O16: PENDENTE VALIDAÇÃO | P16: CMO - Reparo | Q16: Chat | R16: Normalizado Sem Intervenção | U16: 166275 | V16: 166275, 166327 | W16: 166275 | X16: MA | Y16: ZE DOCA | AA16: Até 4h | AB16: 38.333333 | AC16: 34.933334 | AD16: 3.399999 | AE16: 0.566666 | AF16: 0 | AG16: 2.833333 | AH16: 2.833333 | AI16: 1.45 | AJ16: 1.383333 | AK16: 0 | AN16: Sem data de ativação | AO16: ZED/FBR/74371/9 | AP16: MA, PA, PI E AP | AQ16: C.32 - Maranhão | AR16: Wellington Marcio | AT16: S01 | AU16: 2026 | AV16: 1 | AW16: MA INT | AX16: 1 | AY16: 0 | BT16: MA INT | BU16: 1 | BV16: 0
A17: 5743925 | B17: 03012026-88271 | C17: JF COMERCIO E SERVICOS OPTICOS LTDA | INDISPONIBIDADE| SLS/FBR/229099/23 | D17: Joao Victor Santos Medeiros | E17: Corporativo | F17: 23 | G17: 58375 | H17: 315 | I17: SUPER LIGEIRO CORPORATIVO | J17: 229099 | K17: JF COMERCIO E SERVICOS OPTICOS LTDA | L17: 47.812.518/0001-93 | M17: 46025.516 | N17: 46027.378 | O17: PENDENTE VALIDAÇÃO | P17: CMO - Reparo | Q17: Chat | R17: Normalizado Sem Intervenção | U17: 166395 | V17: 166395 | X17: MA | Y17: SAO LUIS | AA17: Até 4h | AB17: 44.616667 | AC17: 39.733334 | AD17: 4.883333 | AE17: 1.483333 | AF17: 0 | AG17: 3.4 | AH17: 3.4 | AI17: 2.716667 | AJ17: 0.683333 | AK17: 0 | AL17: 42991 | AM17: 3034 | AN17: Maior que 15d pós ativação | AO17: SLS/FBR/229099/23 | AP17: MA, PA, PI E AP | AQ17: C.32 - Maranhão | AR17: Wellington Marcio | AT17: S02 | AU17: 2026 | AV17: 1 | AW17: MA CAP | AX17: 1 | AY17: 0 | BT17: MA CAP | BU17: 1 | BV17: 0
A18: 5742833 | B18: 02012026-79262 | C18: Perda de Conexão | D18: Stephanie Aparecida Arthur | E18: Corporativo | F18: 1 | G18: 344359 | H18: 450 | I18: IP CONNECT GPON | J18: 228519 | K18: MARANHAO MOTOSSERRAS E MAQUINAS LTDA MARANHAO MOTOSSERRAS E MAQUINAS | L18: 01.501.831/0001-00 | M18: 46024.626 | N18: 46027.425 | O18: PENDENTE VALIDAÇÃO | P18: CMO - Reparo | Q18: Portal do Cliente | R18: Rompimento de Fibra | U18: 166301 | V18: 166205, 166229, 166301 | W18: 166301 | X18: MA | Y18: SAO LUIS | AA18: Entre 4h e 8h | AB18: 67.100002 | AC18: 61.583334 | AD18: 5.516668 | AE18: 0.133334 | AF18: 0 | AG18: 5.383334 | AH18: 5.383334 | AI18: 5.133334 | AJ18: 0.25 | AK18: 0 | AL18: 45917 | AM18: 107 | AN18: Maior que 15d pós ativação | AO18: SLS/IPD/228519/1 | AP18: MA, PA, PI E AP | AQ18: C.32 - Maranhão | AR18: Wellington Marcio | AT18: S02 | AU18: 2026 | AV18: 1 | AW18: MA CAP | AX18: 1 | AY18: 0 | BT18: MA CAP | BU18: 1 | BV18: 0
A19: 5742785 | B19: 02012026-17277 | C19: Atendimento para: POSTO SALVA VIDA - PONTA DA AREIA - VLAN-4012 SLS-216233-00422 | D19: Stephanie Aparecida Arthur | E19: Público | F19: 422 | G19: 289265 | H19: 740.61 | I19: LINK DE DADOS | J19: 216233 | K19: MUNICIPIO DE SAO LUIS SEMIT | L19: 06.307.102/0001-30 | M19: 46024.612 | N19: 46027.427 | O19: PENDENTE VALIDAÇÃO | P19: CMO - Reparo | Q19: Email | R19: Ajuste de Atenuação | U19: 166189 | V19: 166189 | W19: 166189 | X19: MA | Y19: SAO LUIS | AA19: Entre 4h e 8h | AB19: 67.516667 | AC19: 62.7 | AD19: 4.816667 | AE19: 0.05 | AF19: 0 | AG19: 4.766667 | AH19: 4.766667 | AI19: 4.766667 | AJ19: 0 | AK19: 0 | AL19: 45021 | AM19: 1003 | AN19: Maior que 15d pós ativação | AO19: SLS/L2L/216233/422 | AP19: MA, PA, PI E AP | AQ19: C.32 - Maranhão | AR19: Wellington Marcio | AT19: S02 | AU19: 2026 | AV19: 1 | AW19: MA CAP | AX19: 1 | AY19: 0 | BT19: MA CAP | BU19: 1 | BV19: 0
A20: 5743875 | B20: 03012026-86894 | C20: CAIXA ECONOMICA FEDERAL | INDISPONIBILIDADE | SLS/L2L/204393/731 | D20: Stephanie Aparecida Arthur | E20: Público | F20: 731 | G20: 244513 | H20: 763.82 | I20: LINK DE DADOS | J20: 204393 | K20: CAIXA ECONOMICA FEDERAL CAIXA ECONOMICA FEDERAL CEF MATRIZ | L20: 00.360.305/0001-04 | M20: 46025.492 | N20: 46027.434 | O20: PENDENTE VALIDAÇÃO | P20: CMO - Reparo | Q20: Chat | R20: Normalizado Sem Intervenção | U20: 166397 | V20: 166397 | X20: MA | Y20: SAO LUIS | AA20: Até 4h | AB20: 46.566667 | AC20: 43.4 | AD20: 3.166667 | AE20: 2.266667 | AF20: 0 | AG20: 0.9 | AH20: 0.9 | AI20: 0.4 | AJ20: 0.5 | AK20: 0 | AL20: 44420 | AM20: 1605 | AN20: Maior que 15d pós ativação | AO20: SLS/L2L/204393/731 | AP20: MA, PA, PI E AP | AQ20: C.32 - Maranhão | AR20: Wellington Marcio | AT20: S02 | AU20: 2026 | AV20: 1 | AW20: MA CAP | AX20: 1 | AY20: 0 | BT20: MA CAP | BU20: 1 | BV20: 0
A21: 5745737 | B21: 05012026-20487 | C21: DISTRIBUIDORA CUMMINS DIESEL DO NORDESTE LTDA | INDISPONIBILIDADE | TSA/IPD/226465/1 | D21: ANA PAULA DA SILVA SANTOS | E21: Corporativo | F21: 1 | G21: 333769 | H21: 330 | I21: IP CONNECT GPON | J21: 226465 | K21: DISTRIBUIDORA CUMMINS DIESEL DO NORDESTE LTDA | L21: 07.301.609/0012-00 | M21: 46027.354 | N21: 46027.445 | O21: PENDENTE VALIDAÇÃO | P21: CMO - Reparo | Q21: Chat | R21: Rompimento de Fibra | U21: 166659 | V21: 166659 | W21: 166659 | X21: PI | Y21: TERESINA | AA21: Até 4h | AB21: 2.133333 | AC21: 0.2 | AD21: 1.933333 | AE21: 0.083333 | AF21: 0 | AG21: 1.85 | AH21: 1.85 | AI21: 1.833333 | AJ21: 0.016667 | AK21: 0 | AL21: 45750.556 | AM21: 276 | AN21: Maior que 15d pós ativação | AO21: TSA/IPD/226465/1 | AP21: MA, PA, PI E AP | AQ21: C.31 - Piaui | AR21: Wellington Marcio | AT21: S02 | AU21: 2026 | AV21: 1 | AW21: PI CAP | AX21: 1 | AY21: 0 | BT21: PI CAP | BU21: 1 | BV21: 0
A22: 5743249 | B22: 02012026-62698 | C22: ALERTA: CLI | IFMA.SIS.SANTA-INES - FALHA | D22: Vanessa Alves Ferreira | E22: Público | F22: 1 | G22: 250779 | H22: 2000 | I22: LINK DEDICADO DE INTERNET | J22: 203401 | K22: INSTITUTO FEDERAL DE EDUCACAO CIENCIA E TECNOLOGIA DO MARANHAO INSTITUTO FEDERAL DO MARANHAO CAMPUS SANTA INES | L22: 10.735.145/0009-41 | M22: 46024.882 | N22: 46027.448 | O22: PENDENTE VALIDAÇÃO | P22: CMO - Reparo | Q22: Email | R22: Normalizado Sem Intervenção | T22: ATEX NET TELECOMUNICAÇÕES LTDA | U22: 166285 | V22: 166285 | W22: 166285 | X22: MA | Y22: SANTA INES | AA22: Até 4h | AB22: 61.466668 | AC22: 52.933334 | AD22: 8.533334 | AE22: 4.55 | AF22: 0 | AG22: 3.983334 | AH22: 3.983334 | AI22: 2.283334 | AJ22: 1.7 | AK22: 0 | AL22: 44650 | AM22: 1374 | AN22: Maior que 15d pós ativação | AO22: SIS/IPD/203401/1 | AP22: MA, PA, PI E AP | AQ22: C.32 - Maranhão | AR22: Wellington Marcio | AT22: S02 | AU22: 2026 | AV22: 1 | AW22: MA INT | AX22: 1 | AY22: 0 | BT22: MA INT | BU22: 1 | BV22: 0
A23: 5743653 | B23: 03012026-46031 | C23: Indisponivel - São Luis | INOVANET | SLS/L2L/133341/17 | D23: Stephanie Aparecida Arthur | E23: Provedores | F23: 17 | G23: 342777 | H23: 250 | I23: L2L Metro | J23: 133341 | K23: INOVANET EMPREENDIMENTOS LTDA. INOVANET | L23: 21.278.402/0001-22 | M23: 46025.359 | N23: 46027.472 | O23: PENDENTE VALIDAÇÃO | P23: CMO - Reparo | Q23: Chat | R23: Falha Elétrica Cliente | U23: 166525 | V23: 166353, 166525 | W23: 166525 | X23: MA | Y23: SAO LUIS | AA23: Entre 8h e 12h | AB23: 50.599998 | AC23: 40.899999 | AD23: 9.699999 | AE23: 0.466666 | AF23: 0 | AG23: 9.233333 | AH23: 9.233333 | AI23: 7.95 | AJ23: 1.283333 | AK23: 0 | AL23: 45996.736 | AM23: 28 | AN23: Maior que 15d pós ativação | AO23: SLS/L2L/133341/17 | AP23: MA, PA, PI E AP | AQ23: C.32 - Maranhão | AR23: Wellington Marcio | AT23: S02 | AU23: 2026 | AV23: 1 | AW23: MA CAP | AX23: 0 | AY23: 0 | BT23: MA CAP | BU23: 0 | BV23: 0
A24: 5743677 | B24: 03012026-95775 | C24: ALERTA: CLI | UFPI.FLO.FLORIANO.IPD.209013.3 - FALHA | D24: Vinicius da Silva Dos Santos | E24: Público | F24: 3 | G24: 280783 | H24: 6464.5 | I24: INTERNET DEDICADA - SCM(Wire) | J24: 209013 | K24: Universidade Federal do Piaui | L24: 06.517.387/0001-34 | M24: 46025.376 | N24: 46027.526 | O24: PENDENTE VALIDAÇÃO | P24: CMO - Reparo | Q24: Email | R24: Normalizado Sem Intervenção | U24: 166553 | V24: 166331, 166553 | X24: PI | Y24: FLORIANO | AA24: Entre 4h e 8h | AB24: 51.5 | AC24: 46.866666 | AD24: 4.633334 | AE24: 0.283333 | AF24: 0 | AG24: 4.350001 | AH24: 4.350001 | AI24: 1.316667 | AJ24: 3.033334 | AK24: 0 | AL24: 44834 | AM24: 1191 | AN24: Maior que 15d pós ativação | AO24: FLO/IPD/209013/3 | AP24: MA, PA, PI E AP | AQ24: C.31 - Piaui | AR24: Wellington Marcio | AT24: S02 | AU24: 2026 | AV24: 1 | AW24: PI INT | AX24: 1 | AY24: 0 | BT24: PI INT | BU24: 1 | BV24: 0
A25: 5744179 | B25: 03012026-45902 | C25: SECOPI SERVICOS COMERCIAS DO PIAUI | INDISPONIBILIDADE | TSA/L2L/41553/791 | D25: Laura Beatriz de Sibia Santos | E25: Corporativo | F25: 791 | G25: 287085 | H25: 209.66 | I25: LINK DE DADOS | J25: 41553 | K25: SECOPI SERVICOS COMERCIAS DO PIAUI LTDA GRUPO SERVIS | L25: 03.582.594/0001-84 | M25: 46025.678 | N25: 46027.529 | O25: PENDENTE VALIDAÇÃO | P25: CMO - Reparo | Q25: Chat | R25: Ajuste de Atenuação | U25: 166441 | V25: 166411, 166441 | W25: 166441 | X25: PI | Y25: TERESINA | AA25: Entre 4h e 8h | AB25: 44.333334 | AC25: 36.716667 | AD25: 7.616667 | AE25: 0.133334 | AF25: 0 | AG25: 7.483333 | AH25: 7.483333 | AI25: 7.45 | AJ25: 0.033333 | AK25: 0 | AL25: 45058 | AM25: 967 | AN25: Maior que 15d pós ativação | AO25: TSA/L2L/41553/791 | AP25: MA, PA, PI E AP | AQ25: C.31 - Piaui | AR25: Wellington Marcio | AT25: S02 | AU25: 2026 | AV25: 1 | AW25: PI CAP | AX25: 1 | AY25: 0 | BT25: PI CAP | BU25: 1 | BV25: 0
A26: 5743831 | B26: 03012026-48961 | C26: sem conexão | D26: Julia Ferreira Costa Silva | E26: Corporativo | F26: 11 | G26: 295427 | H26: 200 | I26: LINK DE DADOS | J26: 218297 | K26: J FEITOSA SILVA FILHO LOJAS SANTA MARIA | L26: 05.017.606/0001-53 | M26: 46025.472 | N26: 46027.653 | O26: PENDENTE VALIDAÇÃO | P26: CMO - Reparo | Q26: Portal do Cliente | R26: Rompimento de Fibra | U26: 166529 | V26: 166367, 166529 | W26: 166529 | X26: MA | Y26: SAO LUIS | AA26: Entre 4h e 8h | AB26: 52.299998 | AC26: 44.233333 | AD26: 8.066665 | AE26: 0.233333 | AF26: 0 | AG26: 7.833332 | AH26: 7.833332 | AI26: 6.499999 | AJ26: 1.333333 | AK26: 0 | AL26: 45293.488 | AM26: 731 | AN26: Maior que 15d pós ativação | AO26: SLS/L2L/218297/11 | AP26: MA, PA, PI E AP | AQ26: C.32 - Maranhão | AR26: Wellington Marcio | AT26: S02 | AU26: 2026 | AV26: 1 | AW26: MA CAP | AX26: 1 | AY26: 0 | BT26: MA CAP | BU26: 1 | BV26: 0
A27: 5746425 | B27: 05012026-37950 | C27: IBL BANDA LARGA INTERNET | INDISPONIBILIDADE | ITZ-L2L-MOJ-F-#102506 | D27: HOANNA MARIA DA SILVA ALBUQUERQUE | E27: Provedores | F27: 4 | G27: 270677 | H27: 51250 | I27: TRANSPORTE LAN TO LAN(Wire) | J27: 210723 | K27: IBL BANDA LARGA INTERNET INFORMATICA LTDA I B L | L27: 08.854.699/0001-69 | M27: 46027.478 | N27: 46027.753 | O27: AGUARDANDO LIBERAÇÃO DE ACESSO | P27: CMO - Reparo | Q27: Chat | R27: Normalizado Sem Intervenção | U27: 166933 | V27: 166933 | X27: MA | Y27: IMPERATRIZ | AA27: Até 4h | AB27: 6.55 | AC27: 2.566667 | AD27: 3.983333 | AE27: 0.383333 | AF27: 0 | AG27: 3.6 | AH27: 3.6 | AI27: 3.45 | AJ27: 0.15 | AK27: 0 | AL27: 36526 | AM27: 9501 | AN27: Maior que 15d pós ativação | AO27: FLA/L2L/210723/4 | AP27: MA, PA, PI E AP | AQ27: C.32 - Maranhão | AR27: Wellington Marcio | AT27: S02 | AU27: 2026 | AV27: 1 | AW27: MA INT | AX27: 1 | AY27: 0 | BT27: MA INT | BU27: 1 | BV27: 0
A28: 5747347 | B28: 05012026-89943 | C28: IAP COSMETICOS LTDA| SLS/IPD/56175/5| INDISPONIBILIDADE | D28: INGRID DA SILVA CALIXTO SANTANA | E28: Corporativo | F28: 5 | G28: 53503 | H28: 402.42 | I28: LINK DEDICADO DE INTERNET | J28: 56175 | K28: IAP COSMETICOS LTDA | L28: 05.346.644/0031-75 | M28: 46027.668 | N28: 46027.775 | O28: AGUARDANDO DISPONIBILIDADE TECNICA | P28: CMO - Reparo | Q28: Chat | R28: Normalizado Sem Intervenção | U28: 167141 | V28: 167141 | X28: MA | Y28: SAO LUIS | AA28: Até 4h | AB28: 2.533333 | AC28: 0 | AD28: 2.533333 | AE28: 0.5 | AF28: 0 | AG28: 2.033333 | AI28: 1.75 | AJ28: 0.283333 | AK28: 0 | AL28: 42625.625 | AM28: 3402 | AN28: Maior que 15d pós ativação | AO28: SLS/IPD/56175/5 | AP28: MA, PA, PI E AP | AQ28: C.32 - Maranhão | AR28: Wellington Marcio | AT28: S02 | AU28: 2026 | AV28: 1 | AW28: MA CAP | AX28: 1 | AY28: 0 | BT28: MA CAP | BU28: 1 | BV28: 0
A29: 5740853 | B29: 01012026-39828 | C29: Indisponibilidade de LantoLan | FILIAL 06 - L2L - GIGA | Grupo TUPAN | D29: ANDRESSA CHRISTINE MOREIRA DA SILVA | E29: Corporativo | F29: 3 | G29: 292843 | H29: 995.89 | I29: LINK DE DADOS | J29: 21243 | K29: DISTRIBUIDORA ADAUTO CARVALHO LTDA | L29: 08.072.649/0002-00 | M29: 46023.028 | N29: 46027.807 | O29: PENDENTE VALIDAÇÃO | P29: CMO - Reparo | Q29: Email | R29: Rompimento de Fibra | U29: 166939 | V29: 165909, 166333, 166939 | W29: 166939 | X29: MA | Y29: TIMON | AA29: Entre 8h e 12h | AB29: 114.56667 | AC29: 101.56667 | AD29: 13 | AE29: 1.95 | AF29: 0 | AG29: 11.05 | AH29: 11.05 | AI29: 8.883333 | AJ29: 2.166667 | AK29: 0 | AL29: 45281.609 | AM29: 741 | AN29: Maior que 15d pós ativação | AO29: TMN/L2L/21243/3 | AP29: MA, PA, PI E AP | AQ29: C.32 - Maranhão | AR29: Wellington Marcio | AT29: S02 | AU29: 2026 | AV29: 1 | AW29: MA INT | AX29: 0 | AY29: 0 | BT29: MA INT | BU29: 0 | BV29: 0
A30: 5740031 | B30: 31122025-28032 | C30: ABERTURA DE REPARO ( LOJA 1132 - LINK MOB INOPERANTE ) | D30: ANDRESSA CHRISTINE MOREIRA DA SILVA | E30: Corporativo | F30: 546 | G30: 65165 | H30: 304.88 | I30: LINK DEDICADO DE INTERNET | J30: 6421 | K30: EMPREENDIMENTOS PAGUE MENOS SA PAGUE MENOS | L30: 06.626.253/0001-51 | M30: 46022.487 | N30: 46027.817 | O30: PENDENTE VALIDAÇÃO | P30: CMO - Reparo | Q30: Email | R30: Rompimento de Fibra | U30: 166521 | V30: 165837, 165979, 166521 | W30: 166521 | X30: MA | Y30: SAO LUIS | AA30: Maior que 24h | AB30: 127.73333 | AC30: 74.95 | AD30: 52.783333 | AE30: 0.316666 | AF30: 0 | AG30: 52.466667 | AH30: 52.466667 | AI30: 42.016667 | AJ30: 10.45 | AK30: 0 | AL30: 43088 | AM30: 2934 | AN30: Maior que 15d pós ativação | AO30: SLS/IPD/6421/546 | AP30: MA, PA, PI E AP | AQ30: C.32 - Maranhão | AR30: Wellington Marcio | AT30: S02 | AU30: 2026 | AV30: 1 | AW30: MA CAP | AX30: 0 | AY30: 1 | BT30: MA CAP | BU30: 0 | BV30: 1
A31: 5740003 | B31: 31122025-97825 | C31: IAP COSMETICOS LTDA || Indisponibilidade || SLS/IPD/56169/7 | D31: ANDRESSA CHRISTINE MOREIRA DA SILVA | E31: Corporativo | F31: 7 | G31: 53523 | H31: 371.35 | I31: LINK DEDICADO DE INTERNET | J31: 56169 | K31: IAP COSMETICOS LTDA | L31: 05.346.644/0033-37 | M31: 46022.472 | N31: 46027.822 | O31: PENDENTE VALIDAÇÃO | P31: CMO - Reparo | Q31: Chat | R31: Rompimento de Fibra | U31: 166523 | V31: 165823, 165981, 166523, 166965 | W31: 166523 | X31: MA | Y31: SAO LUIS | AA31: Maior que 24h | AB31: 128.23333 | AC31: 85.066666 | AD31: 43.166668 | AE31: 0.116667 | AF31: 0 | AG31: 43.050001 | AH31: 43.050001 | AI31: 43.033334 | AJ31: 0.016667 | AK31: 0 | AL31: 42843 | AM31: 3179 | AN31: Maior que 15d pós ativação | AO31: SLS/IPD/56169/7 | AP31: MA, PA, PI E AP | AQ31: C.32 - Maranhão | AR31: Wellington Marcio | AT31: S02 | AU31: 2026 | AV31: 1 | AW31: MA CAP | AX31: 0 | AY31: 1 | BT31: MA CAP | BU31: 0 | BV31: 1
A32: 5744841 | B32: 04012026-60706 | C32: MOBWIRE - ALERTA: CLI | PADRE CICERO MATRIZ MONTESE | D32: Vinicius da Silva Dos Santos | E32: Corporativo | F32: 16 | G32: 298395 | H32: 640 | I32: LINK DE DADOS | J32: 202197 | K32: AUTO PECAS PADRE CICERO LTDA 0 | L32: 07.965.809/0001-05 | M32: 46026.473 | N32: 46028.359 | O32: PENDENTE VALIDAÇÃO | P32: CMO - Reparo | Q32: Email | R32: Ajuste de Atenuação | U32: 166539 | V32: 166477, 166539 | W32: 166477 | X32: MA | Y32: SAO LUIS | AA32: Até 4h | AB32: 45.216667 | AC32: 40.966667 | AD32: 4.25 | AE32: 0.516667 | AF32: 0 | AG32: 3.733333 | AH32: 3.733333 | AI32: 3.666667 | AJ32: 0.066666 | AK32: 0 | AL32: 45302 | AM32: 724 | AN32: Maior que 15d pós ativação | AO32: SLS/L2L/202197/16 | AP32: MA, PA, PI E AP | AQ32: C.32 - Maranhão | AR32: Wellington Marcio | AT32: S02 | AU32: 2026 | AV32: 1 | AW32: MA CAP | AX32: 1 | AY32: 0 | BT32: MA CAP | BU32: 1 | BV32: 0
A33: 5745147 | B33: 04012026-34348 | C33: Atendimento para: CAPS I RH - VLAN-3670 SLS-216233-00114 | D33: Vinicius da Silva Dos Santos | E33: Público | F33: 114 | G33: 285557 | H33: 368.16 | I33: LINK DE DADOS | J33: 218791 | K33: FUNDO MUNICIPAL DE SAUDE DE SAO LUIS MARANHAO | L33: 13.816.886/0001-98 | M33: 46026.806 | N33: 46028.362 | O33: PENDENTE VALIDAÇÃO | P33: CMO - Reparo | Q33: Email | R33: Rompimento de Fibra | U33: 166533 | V33: 166499, 166533 | W33: 166499 | X33: MA | Y33: SAO LUIS | AA33: Até 4h | AB33: 37.266666 | AC33: 33.1 | AD33: 4.166666 | AE33: 0.316666 | AF33: 0 | AG33: 3.85 | AH33: 3.85 | AI33: 3.65 | AJ33: 0.2 | AK33: 0 | AL33: 44874.648 | AM33: 1152 | AN33: Maior que 15d pós ativação | AO33: SLS/L2L/218791/114 | AP33: MA, PA, PI E AP | AQ33: C.32 - Maranhão | AR33: Wellington Marcio | AT33: S02 | AU33: 2026 | AV33: 1 | AW33: MA CAP | AX33: 1 | AY33: 0 | BT33: MA CAP | BU33: 1 | BV33: 0
A34: 5744145 | B34: 03012026-94698 | C34: Atendimento para: POSTO SALVA VIDA - PONTA DA AREIA - VLAN-4012 SLS-216233-00422 | D34: Vinicius da Silva Dos Santos | E34: Público | F34: 422 | G34: 289265 | H34: 740.61 | I34: LINK DE DADOS | J34: 216233 | K34: MUNICIPIO DE SAO LUIS SEMIT | L34: 06.307.102/0001-30 | M34: 46025.667 | N34: 46028.364 | O34: PENDENTE VALIDAÇÃO | P34: CMO - Reparo | Q34: Email | R34: Rompimento de Fibra | U34: 166531 | V34: 166531 | W34: 166531 | X34: MA | Y34: SAO LUIS | AA34: Entre 8h e 12h | AB34: 64.65 | AC34: 54 | AD34: 10.65 | AE34: 0.783333 | AF34: 0 | AG34: 9.866667 | AH34: 9.866667 | AI34: 9.283334 | AJ34: 0.583333 | AK34: 0 | AL34: 45021 | AM34: 1004 | AN34: Maior que 15d pós ativação | AO34: SLS/L2L/216233/422 | AP34: MA, PA, PI E AP | AQ34: C.32 - Maranhão | AR34: Wellington Marcio | AT34: S02 | AU34: 2026 | AV34: 1 | AW34: MA CAP | AX34: 0 | AY34: 0 | BT34: MA CAP | BU34: 0 | BV34: 0
A35: 5743523 | B35: 03012026-38870 | C35: Atendimento para: UEB ENS FUND URUATI - SLS-216233-00375 | D35: Vinicius da Silva Dos Santos | E35: Público | F35: 375 | G35: 286793 | H35: 364.96 | I35: LINK DE DADOS | J35: 218787 | K35: MUNICIPIO DE SAO LUIS SEMED | L35: 06.307.102/0002-11 | M35: 46025.216 | N35: 46028.365 | O35: PENDENTE VALIDAÇÃO | P35: CMO - Reparo | Q35: Email | R35: Ajuste de Atenuação | U35: 166551 | V35: 166289, 166551 | W35: 166551 | X35: MA | Y35: SAO LUIS | AA35: Entre 4h e 8h | AB35: 75.516666 | AC35: 70.583333 | AD35: 4.933333 | AE35: 0.483333 | AF35: 0 | AG35: 4.45 | AH35: 4.45 | AI35: 3.066667 | AJ35: 1.383333 | AK35: 0 | AL35: 44939 | AM35: 1086 | AN35: Maior que 15d pós ativação | AO35: SLS/L2L/218787/375 | AP35: MA, PA, PI E AP | AQ35: C.32 - Maranhão | AR35: Wellington Marcio | AT35: S02 | AU35: 2026 | AV35: 1 | AW35: MA CAP | AX35: 1 | AY35: 0 | BT35: MA CAP | BU35: 1 | BV35: 0
A36: 5745245 | B36: 04012026-75805 | C36: Atendimento para: UEB PROTECAO DE JESUS e UEB ENS FUND PROTECAO DE JESUS - SLS-216233-00393 | D36: Vinicius da Silva Dos Santos | E36: Público | F36: 393 | G36: 286891 | H36: 364.96 | I36: LINK DE DADOS | J36: 218787 | K36: MUNICIPIO DE SAO LUIS SEMED | L36: 06.307.102/0002-11 | M36: 46026.931 | N36: 46028.366 | O36: PENDENTE VALIDAÇÃO | P36: CMO - Reparo | Q36: Email | R36: Rompimento de Fibra | U36: 166513 | V36: 166513, 166535 | W36: 166513 | X36: MA | Y36: SAO LUIS | AA36: Entre 4h e 8h | AB36: 34.383334 | AC36: 26.416667 | AD36: 7.966667 | AE36: 0.2 | AF36: 0 | AG36: 7.766667 | AH36: 7.766667 | AI36: 7.4 | AJ36: 0.366667 | AK36: 0 | AL36: 44974 | AM36: 1052 | AN36: Maior que 15d pós ativação | AO36: SLS/L2L/218787/393 | AP36: MA, PA, PI E AP | AQ36: C.32 - Maranhão | AR36: Wellington Marcio | AT36: S02 | AU36: 2026 | AV36: 1 | AW36: MA CAP | AX36: 1 | AY36: 0 | BT36: MA CAP | BU36: 1 | BV36: 0
A37: 5747277 | B37: 05012026-44302 | C37: LINK INOPERANTE - LOJA 20 - GUAXENDUBA | D37: Vinicius da Silva Dos Santos | E37: Corporativo | F37: 16 | G37: 50431 | H37: 300 | I37: LINK DE DADOS | J37: 13955 | K37: PFM COMERCIAL LTDA - CASA FREITAS | L37: 01.740.627/0001-41 | M37: 46027.656 | N37: 46028.395 | O37: PENDENTE VALIDAÇÃO | P37: CMO - Reparo | Q37: Portal do Cliente | R37: Normalizado Sem Intervenção | U37: 167221 | V37: 167091, 167173, 167221, 167437 | W37: 167173 | X37: MA | Y37: SAO LUIS | AA37: Até 4h | AB37: 17.666666 | AC37: 14.299999 | AD37: 3.366667 | AE37: 0.216667 | AF37: 0 | AG37: 3.15 | AH37: 3.15 | AI37: 3 | AJ37: 0.15 | AK37: 0 | AL37: 42332 | AM37: 3695 | AN37: Maior que 15d pós ativação | AO37: SLS/L2L/13955/16 | AP37: MA, PA, PI E AP | AQ37: C.32 - Maranhão | AR37: Wellington Marcio | AT37: S02 | AU37: 2026 | AV37: 1 | AW37: MA CAP | AX37: 1 | AY37: 0 | BT37: MA CAP | BU37: 1 | BV37: 0
A38: 5746191 | B38: 05012026-34268 | C38: sem conexão | D38: Vinicius da Silva Dos Santos | E38: Corporativo | F38: 9 | G38: 295423 | H38: 200 | I38: LINK DE DADOS | J38: 218297 | K38: J FEITOSA SILVA FILHO LOJAS SANTA MARIA | L38: 05.017.606/0001-53 | M38: 46027.431 | N38: 46028.419 | O38: PENDENTE VALIDAÇÃO | P38: CMO - Reparo | Q38: Portal do Cliente | R38: Rompimento de Fibra | U38: 166879 | V38: 166879 | W38: 166879 | X38: MA | Y38: SAO LUIS | AA38: Entre 4h e 8h | AB38: 23.633333 | AC38: 17.316667 | AD38: 6.316666 | AE38: 0.233333 | AF38: 0 | AG38: 6.083333 | AH38: 6.083333 | AI38: 6.05 | AJ38: 0.033333 | AK38: 0 | AL38: 45293.489 | AM38: 733 | AN38: Maior que 15d pós ativação | AO38: SLS/L2L/218297/9 | AP38: MA, PA, PI E AP | AQ38: C.32 - Maranhão | AR38: Wellington Marcio | AT38: S02 | AU38: 2026 | AV38: 1 | AW38: MA CAP | AX38: 1 | AY38: 0 | BT38: MA CAP | BU38: 1 | BV38: 0
A39: 5746745 | B39: 05012026-22407 | C39: GR NET TELECOMUNICACOES LTDA GR NET || Indisponibilidade || NMB/IPD/214735/1 | D39: Stephanie Aparecida Arthur | E39: Provedores | F39: 1 | G39: 269667 | H39: 2310 | I39: INTERNET DEDICADA - SCM(Wire) | J39: 214735 | K39: GR NET TELECOMUNICACOES LTDA GR NET | L39: 40.089.789/0001-13 | M39: 46027.538 | N39: 46028.438 | O39: PENDENTE VALIDAÇÃO | P39: CMO - Reparo | Q39: Telefone | R39: Normalizado Sem Intervenção | T39: ONLINE NORTE TELECOM LTDA | U39: 167037 | V39: 167037, 167049 | W39: 167037 | X39: PA | Y39: NOVA TIMBOTEUA | AA39: Até 4h | AB39: 21.566667 | AC39: 19.583333 | AD39: 1.983334 | AE39: 1.233334 | AF39: 0 | AG39: 0.75 | AH39: 0.75 | AI39: 0.716667 | AJ39: 0.033333 | AK39: 0 | AL39: 36526 | AM39: 9501 | AN39: Maior que 15d pós ativação | AO39: NMB/IPD/214735/1 | AP39: MA, PA, PI E AP | AQ39: C.28 - Norte | AR39: Wellington Marcio | AT39: S02 | AU39: 2026 | AV39: 1 | AW39: PA INT | AX39: 1 | AY39: 0 | BT39: PA INT | BU39: 1 | BV39: 0
A40: 5743995 | B40: 03012026-19233 | C40: ALERTA: CLI | MPMA.SLS.CONCENTRADOR.REDUNDANTE.L2L.149307.22 - FALHA | D40: Vinicius da Silva Dos Santos | E40: Público | F40: 22 | G40: 279675 | H40: 0 | I40: INTERNET DEDICADA - SCM(Wire) | J40: 149307 | K40: ESTADO DO MARANHAO PROCURADORIA GERAL DA JUSTICA PROCURADORIA GERAL DA JUSTICA | L40: 05.483.912/0001-85 | M40: 46025.563 | N40: 46028.496 | O40: PENDENTE VALIDAÇÃO | P40: CMO - Reparo | Q40: Email | R40: Ajuste de Atenuação | U40: 166537 | V40: 166537 | W40: 166537 | X40: MA | Y40: SAO LUIS | AA40: Entre 4h e 8h | AB40: 70.333332 | AC40: 64.383333 | AD40: 5.949999 | AE40: 1.233333 | AF40: 0 | AG40: 4.716666 | AH40: 4.716666 | AI40: 1.816666 | AJ40: 2.9 | AK40: 0 | AL40: 44767 | AM40: 1258 | AN40: Maior que 15d pós ativação | AO40: SLS/IPD/149307/22 | AP40: MA, PA, PI E AP | AQ40: C.32 - Maranhão | AR40: Wellington Marcio | AT40: S02 | AU40: 2026 | AV40: 1 | AW40: MA CAP | AX40: 1 | AY40: 0 | BT40: MA CAP | BU40: 1 | BV40: 0
...

Sheet CONTROLE
A1: 📋 CONTROLE DE CHAMADOS — GESTÃO SEMANAL B2B
A2: Atualização automática via BASE BI | Selecione a semana para filtrar todos os indicadores
B4: SELEÇÃO DE SEMANA | F4: METAS EDITÁVEIS
B5: Semana do Ano: | D5: S16 | F5: B2B Reparo ≤8h (meta ≥): | I5: 0.85
D6: =VALUE(MID(D5,2,LEN(D5)-1)) -> 16 | F6: B2B Outlier >24h (teto ≤): | I6: 0.02
B7: Data Início: | D7: =DATE(2026,1,1)+((D6-1)*7)-WEEKDAY(DATE(2026,1,1),2)+1 -> 46125 | F7: * Edite diretamente as células I5 e I6 para alterar as metas
B8: Data Fim: | D8: =D7+6 -> 46131
B9: Total chamados na semana: | D9: =COUNTIFS('BASE BI'!N:N,">="&D7,'BASE BI'!N:N,"<="&D8+0.99999) -> 106
B11: INDICADORES DA SEMANA SELECIONADA
B12: B2B Reparo ≤8h (Aderência) | E12: B2B Outlier >24h (% casos fora) | H12: Total Chamados Semana | K12: Casos ≤8h (qtd) | N12: Casos >24h (qtd)
B13: =IFERROR(COUNTIFS('BASE BI'!N:N,">="&D7,'BASE BI'!N:N,"<="&D8+0.99999,'BASE BI'!AH:AH,"<="&8)/D9,0) -> 0.39622642 | E13: =IFERROR(COUNTIFS('BASE BI'!N:N,">="&D7,'BASE BI'!N:N,"<="&D8+0.99999,'BASE BI'!AH:AH,">"&24)/D9,0) -> 0.25471698 | H13: =D9 -> 106 | K13: =IFERROR(COUNTIFS('BASE BI'!N:N,">="&D7,'BASE BI'!N:N,"<="&D8+0.99999,'BASE BI'!AH:AH,"<="&8),0) -> 42 | N13: =IFERROR(COUNTIFS('BASE BI'!N:N,">="&D7,'BASE BI'!N:N,"<="&D8+0.99999,'BASE BI'!AH:AH,">"&24),0) -> 27
B14: =IF(D9=0,"SEM DADOS",IF(B13>=I5,"✔ DENTRO DA META","✘ DESVIO: "&TEXT(B13-I5,"0.0%"))) -> ✘ DESVIO: -45% | E14: =IF(D9=0,"SEM DADOS",IF(E13<=I6,"✔ DENTRO DO TETO","✘ ACIMA: +"&TEXT(E13-I6,"0.0%"))) -> ✘ ACIMA: +23%
B16: RESUMO POR CLUSTER / UF — SEMANA SELECIONADA
B17: Cluster / UF | D17: Total | E17: Casos ≤8h | F17: Ader. ≤8h | G17: Meta 85% | H17: Status ≤8h | I17: Casos >24h | J17: % Outlier | K17: Teto 2% | L17: Status >24h
B18: MA CAP (São Luís, Paço, SJR) | D18: =IFERROR(COUNTIFS('BASE BI'!N:N,">="&D7,'BASE BI'!N:N,"<="&D8+0.99999,'BASE BI'!BT:BT,"MA CAP"),0) -> 68 | E18: =IFERROR(COUNTIFS('BASE BI'!N:N,">="&D7,'BASE BI'!N:N,"<="&D8+0.99999,'BASE BI'!BT:BT,"MA CAP",'BASE BI'!AH:AH,"<="&8),0) -> 20 | F18: =IFERROR(E18/D18,0) -> 0.29411765 | G18: =I5 -> 0.85 | H18: =IF(D18=0,"-",IF(F18>=$I$5,"✔ OK","✘ DESVIO")) -> ✘ DESVIO | I18: =IFERROR(COUNTIFS('BASE BI'!N:N,">="&D7,'BASE BI'!N:N,"<="&D8+0.99999,'BASE BI'!BT:BT,"MA CAP",'BASE BI'!AH:AH,">"&24),0) -> 21 | J18: =IFERROR(I18/D18,0) -> 0.30882353 | K18: =I6 -> 0.02 | L18: =IF(D18=0,"-",IF(J18<=$I$6,"✔ OK","✘ DESVIO")) -> ✘ DESVIO
B19: MA INT (demais cidades MA) | D19: =IFERROR(COUNTIFS('BASE BI'!N:N,">="&D7,'BASE BI'!N:N,"<="&D8+0.99999,'BASE BI'!BT:BT,"MA INT"),0) -> 11 | E19: =IFERROR(COUNTIFS('BASE BI'!N:N,">="&D7,'BASE BI'!N:N,"<="&D8+0.99999,'BASE BI'!BT:BT,"MA INT",'BASE BI'!AH:AH,"<="&8),0) -> 6 | F19: =IFERROR(E19/D19,0) -> 0.54545455 | G19: =I5 -> 0.85 | H19: =IF(D19=0,"-",IF(F19>=$I$5,"✔ OK","✘ DESVIO")) -> ✘ DESVIO | I19: =IFERROR(COUNTIFS('BASE BI'!N:N,">="&D7,'BASE BI'!N:N,"<="&D8+0.99999,'BASE BI'!BT:BT,"MA INT",'BASE BI'!AH:AH,">"&24),0) -> 4 | J19: =IFERROR(I19/D19,0) -> 0.36363636 | K19: =I6 -> 0.02 | L19: =IF(D19=0,"-",IF(J19<=$I$6,"✔ OK","✘ DESVIO")) -> ✘ DESVIO
B20: PA CAP (Belém, Ananindeua) | D20: =IFERROR(COUNTIFS('BASE BI'!N:N,">="&D7,'BASE BI'!N:N,"<="&D8+0.99999,'BASE BI'!BT:BT,"PA CAP"),0) -> 6 | E20: =IFERROR(COUNTIFS('BASE BI'!N:N,">="&D7,'BASE BI'!N:N,"<="&D8+0.99999,'BASE BI'!BT:BT,"PA CAP",'BASE BI'!AH:AH,"<="&8),0) -> 5 | F20: =IFERROR(E20/D20,0) -> 0.83333333 | G20: =I5 -> 0.85 | H20: =IF(D20=0,"-",IF(F20>=$I$5,"✔ OK","✘ DESVIO")) -> ✘ DESVIO | I20: =IFERROR(COUNTIFS('BASE BI'!N:N,">="&D7,'BASE BI'!N:N,"<="&D8+0.99999,'BASE BI'!BT:BT,"PA CAP",'BASE BI'!AH:AH,">"&24),0) -> 0 | J20: =IFERROR(I20/D20,0) -> 0 | K20: =I6 -> 0.02 | L20: =IF(D20=0,"-",IF(J20<=$I$6,"✔ OK","✘ DESVIO")) -> ✔ OK
B21: PA INT (demais cidades PA) | D21: =IFERROR(COUNTIFS('BASE BI'!N:N,">="&D7,'BASE BI'!N:N,"<="&D8+0.99999,'BASE BI'!BT:BT,"PA INT"),0) -> 4 | E21: =IFERROR(COUNTIFS('BASE BI'!N:N,">="&D7,'BASE BI'!N:N,"<="&D8+0.99999,'BASE BI'!BT:BT,"PA INT",'BASE BI'!AH:AH,"<="&8),0) -> 1 | F21: =IFERROR(E21/D21,0) -> 0.25 | G21: =I5 -> 0.85 | H21: =IF(D21=0,"-",IF(F21>=$I$5,"✔ OK","✘ DESVIO")) -> ✘ DESVIO | I21: =IFERROR(COUNTIFS('BASE BI'!N:N,">="&D7,'BASE BI'!N:N,"<="&D8+0.99999,'BASE BI'!BT:BT,"PA INT",'BASE BI'!AH:AH,">"&24),0) -> 0 | J21: =IFERROR(I21/D21,0) -> 0 | K21: =I6 -> 0.02 | L21: =IF(D21=0,"-",IF(J21<=$I$6,"✔ OK","✘ DESVIO")) -> ✔ OK
B22: PI | D22: =IFERROR(COUNTIFS('BASE BI'!N:N,">="&D7,'BASE BI'!N:N,"<="&D8+0.99999,'BASE BI'!BT:BT,"PI"),0) -> 0 | E22: =IFERROR(COUNTIFS('BASE BI'!N:N,">="&D7,'BASE BI'!N:N,"<="&D8+0.99999,'BASE BI'!BT:BT,"PI",'BASE BI'!AH:AH,"<="&8),0) -> 0 | F22: =IFERROR(E22/D22,0) -> 0 | G22: =I5 -> 0.85 | H22: =IF(D22=0,"-",IF(F22>=$I$5,"✔ OK","✘ DESVIO")) -> - | I22: =IFERROR(COUNTIFS('BASE BI'!N:N,">="&D7,'BASE BI'!N:N,"<="&D8+0.99999,'BASE BI'!BT:BT,"PI",'BASE BI'!AH:AH,">"&24),0) -> 0 | J22: =IFERROR(I22/D22,0) -> 0 | K22: =I6 -> 0.02 | L22: =IF(D22=0,"-",IF(J22<=$I$6,"✔ OK","✘ DESVIO")) -> -
B23: AM INT | D23: =IFERROR(COUNTIFS('BASE BI'!N:N,">="&D7,'BASE BI'!N:N,"<="&D8+0.99999,'BASE BI'!BT:BT,"AM INT"),0) -> 0 | E23: =IFERROR(COUNTIFS('BASE BI'!N:N,">="&D7,'BASE BI'!N:N,"<="&D8+0.99999,'BASE BI'!BT:BT,"AM INT",'BASE BI'!AH:AH,"<="&8),0) -> 0 | F23: =IFERROR(E23/D23,0) -> 0 | G23: =I5 -> 0.85 | H23: =IF(D23=0,"-",IF(F23>=$I$5,"✔ OK","✘ DESVIO")) -> - | I23: =IFERROR(COUNTIFS('BASE BI'!N:N,">="&D7,'BASE BI'!N:N,"<="&D8+0.99999,'BASE BI'!BT:BT,"AM INT",'BASE BI'!AH:AH,">"&24),0) -> 0 | J23: =IFERROR(I23/D23,0) -> 0 | K23: =I6 -> 0.02 | L23: =IF(D23=0,"-",IF(J23<=$I$6,"✔ OK","✘ DESVIO")) -> -
B24: AP | D24: =IFERROR(COUNTIFS('BASE BI'!N:N,">="&D7,'BASE BI'!N:N,"<="&D8+0.99999,'BASE BI'!BT:BT,"AP"),0) -> 3 | E24: =IFERROR(COUNTIFS('BASE BI'!N:N,">="&D7,'BASE BI'!N:N,"<="&D8+0.99999,'BASE BI'!BT:BT,"AP",'BASE BI'!AH:AH,"<="&8),0) -> 1 | F24: =IFERROR(E24/D24,0) -> 0.33333333 | G24: =I5 -> 0.85 | H24: =IF(D24=0,"-",IF(F24>=$I$5,"✔ OK","✘ DESVIO")) -> ✘ DESVIO | I24: =IFERROR(COUNTIFS('BASE BI'!N:N,">="&D7,'BASE BI'!N:N,"<="&D8+0.99999,'BASE BI'!BT:BT,"AP",'BASE BI'!AH:AH,">"&24),0) -> 0 | J24: =IFERROR(I24/D24,0) -> 0 | K24: =I6 -> 0.02 | L24: =IF(D24=0,"-",IF(J24<=$I$6,"✔ OK","✘ DESVIO")) -> ✔ OK
B25: TOTAL GERAL | D25: =SUM(D18:D24) -> 92 | E25: =SUM(E18:E24) -> 33 | F25: =IFERROR(E25/D25,0) -> 0.35869565 | G25: =I5 -> 0.85 | I25: =SUM(I18:I24) -> 25 | J25: =IFERROR(I25/D25,0) -> 0.27173913 | K25: =I6 -> 0.02

Sheet RELATÓRIO EXECUTIVO
A1: RELATÓRIO EXECUTIVO — TEXTO NARRATIVO A NÍVEL DE DIRETORIA | M1: =CONTROLE!D5&CHAR(10)&TEXT(CONTROLE!D7,"DD/MM")&" a "&TEXT(CONTROLE!D8,"DD/MM") -> S16 13/04 a 19/04
A2: Semana selecionada em CONTROLE | Gerado automaticamente com base nos dados da BASE BI
A4: Total chamados | D4: B2B Reparo ≤8h | G4: Outlier >24h | J4: Localidades c/ desvio
A5: =CONTROLE!D9 -> 106 | D5: =CONTROLE!B13 -> 0.39622642 | G5: =CONTROLE!E13 -> 0.25471698 | J5: =COUNTIF(CONTROLE!H18:H24,"✘ DESVIO") -> 5
A6: ="semana "&CONTROLE!D5 -> semana S16 | D6: ="meta "&TEXT(CONTROLE!I5,"0%")&" | "&TEXT(CONTROLE!B13-CONTROLE!I5,"+0.0%;-0.0%;0.0%")&"pp" -> meta 85% | -45%pp | G6: ="teto "&TEXT(CONTROLE!I6,"0%")&" | "&TEXT(CONTROLE!E13-CONTROLE!I6,"+0.0%;-0.0%;0.0%")&"pp" -> teto 2% | +23%pp | J6: =IF(J5=0,"sem cidades em desvio","cidades impactadas") -> cidades impactadas
A8: ▼ B2B Reparo 8h — Desvio de prazo | 64 casos de 108 (59,26%) | L8: DESVIO CRÍTICO
A9: B2B Reparo 8h – Desvio em 14 localidades representando (64 /108) casos - 59% das perdas de prazo de 8 horas, Sao Luis - MA (45 Casos - 41,67%) devido demais causas de rompimento, Sao Jose De Ribamar - MA (3 Casos - 2,78%) devido demais causas de rompimento, Teresina - PI (3 Casos - 2,78%) devido demais causas configuração, Castanhal - PA (2 Casos - 1,85%) devido demais causas de rompimento, Macapa - AP (2 Casos - 1,85%) devido demais causas de rompimento, Ananindeua - PA (1 Caso - 0,93%) devido demais causas de rompimento, Balsas - MA (1 Caso - 0,93%) devido sem ação, Barra Do Corda - MA (1 Caso - 0,93%) devido demais causas de atenuação, Benevides - PA (1 Caso - 0,93%) devido demais causas de rompimento, Itaporanga - MA (1 Caso - 0,93%) devido demais causas de rompimento, Olinda Nova Do Maranhao - MA (1 Caso - 0,93%) devido demais causas de atenuação, Presidente Dutra - MA (1 Caso - 0,93%) devido demais causas de elétrica, Santa Ines - MA (1 Caso - 0,93%) devido sem ação, Simoes - PI (1 Caso - 0,93%) devido demais causas configuração.
A10: Este texto é gerado automaticamente pela aba RELATÓRIO EXECUTIVO com base nos dados da semana selecionada em CONTROLE. O campo é editável pelo gestor para acrescentar contexto operacional (ex.: obras COP30, condições climáticas, ações de parceiros).
A11: Localidade | C11: UF | D11: Cluster | E11: Casos Fora ≤8h | F11: % do Total | G11: Causa Principal | L11: Parceiro
A12: SAO LUIS | C12: MA | D12: MA CAP | E12: 45 | F12: 0.41666667 | G12: Demais Causas de Rompimento | L12: =IFERROR(INDEX('BASE BI'!T:T,MATCH(A12,'BASE BI'!Y:Y,0)),"—") -> 0
A13: SAO JOSE DE RIBAMAR | C13: MA | D13: MA CAP | E13: 3 | F13: 0.027777778 | G13: Demais Causas de Rompimento | L13: =IFERROR(INDEX('BASE BI'!T:T,MATCH(A13,'BASE BI'!Y:Y,0)),"—") -> NMA SERVICOS DE TELECOMUNICACOES LTDA
A14: TERESINA | C14: PI | D14: PI CAP | E14: 3 | F14: 0.027777778 | G14: Demais Causas Configuração | L14: =IFERROR(INDEX('BASE BI'!T:T,MATCH(A14,'BASE BI'!Y:Y,0)),"—") -> 0
A15: CASTANHAL | C15: PA | D15: PA INT | E15: 2 | F15: 0.018518519 | G15: Demais Causas de Rompimento | L15: =IFERROR(INDEX('BASE BI'!T:T,MATCH(A15,'BASE BI'!Y:Y,0)),"—") -> 0
A16: MACAPA | C16: AP | D16: AP CAP | E16: 2 | F16: 0.018518519 | G16: Demais Causas de Rompimento | L16: =IFERROR(INDEX('BASE BI'!T:T,MATCH(A16,'BASE BI'!Y:Y,0)),"—") -> 0
A17: ANANINDEUA | C17: PA | D17: PA CAP | E17: 1 | F17: 0.0092592593 | G17: Demais Causas de Rompimento | L17: =IFERROR(INDEX('BASE BI'!T:T,MATCH(A17,'BASE BI'!Y:Y,0)),"—") -> 0
A18: BALSAS | C18: MA | D18: MA INT | E18: 1 | F18: 0.0092592593 | G18: Sem Ação | L18: =IFERROR(INDEX('BASE BI'!T:T,MATCH(A18,'BASE BI'!Y:Y,0)),"—") -> 0
A19: BARRA DO CORDA | C19: MA | D19: MA INT | E19: 1 | F19: 0.0092592593 | G19: Demais causas de Atenuação | L19: =IFERROR(INDEX('BASE BI'!T:T,MATCH(A19,'BASE BI'!Y:Y,0)),"—") -> 0
A20: BENEVIDES | C20: PA | D20: PA INT | E20: 1 | F20: 0.0092592593 | G20: Demais Causas de Rompimento | L20: =IFERROR(INDEX('BASE BI'!T:T,MATCH(A20,'BASE BI'!Y:Y,0)),"—") -> 0
A21: ITAPORANGA | C21: MA | D21: MA INT | E21: 1 | F21: 0.0092592593 | G21: Demais Causas de Rompimento | L21: =IFERROR(INDEX('BASE BI'!T:T,MATCH(A21,'BASE BI'!Y:Y,0)),"—") -> —
A22: OLINDA NOVA DO MARANHAO | C22: MA | D22: MA INT | E22: 1 | F22: 0.0092592593 | G22: Demais causas de Atenuação | L22: =IFERROR(INDEX('BASE BI'!T:T,MATCH(A22,'BASE BI'!Y:Y,0)),"—") -> 0
A24: ▲ B2B Outlier >24h — 28 casos de 108 (25,93%) | Teto: 2% | L24: DESVIO CRÍTICO
A25: B2B Outlier >24h – Semana S16 apresentou performance de 25,93% (28/108) devido às causas concentradas nas localidades: Sao Luis - MA (20 Casos - 18,52%) devido demais causas de rompimento, Barra Do Corda - MA (1 Caso - 0,93%) devido demais causas de atenuação, Itaporanga - MA (1 Caso - 0,93%) devido demais causas de rompimento, Olinda Nova Do Maranhao - MA (1 Caso - 0,93%) devido demais causas de atenuação, Presidente Dutra - MA (1 Caso - 0,93%) devido demais causas de elétrica, Santa Ines - MA (1 Caso - 0,93%) devido sem ação, Sao Jose De Ribamar - MA (1 Caso - 0,93%) devido demais causas de rompimento, Simoes - PI (1 Caso - 0,93%) devido demais causas configuração, Teresina - PI (1 Caso - 0,93%) devido demais causas configuração.
A26: Campo editável. O gestor deve incluir contexto executivo adicional como: negociações em andamento com parceiros, planos de contingência, comprometimentos com prazos de normalização e impacto financeiro estimado.
A27: Localidade | C27: UF | D27: Cluster | E27: Casos >24h | F27: % do Total | G27: Causa Principal | L27: Parceiro
A28: SAO LUIS | C28: MA | D28: MA CAP | E28: 20 | F28: 0.18518519 | G28: Demais Causas de Rompimento | L28: =IFERROR(INDEX('BASE BI'!T:T,MATCH(A28,'BASE BI'!Y:Y,0)),"—") -> 0
A29: BARRA DO CORDA | C29: MA | D29: MA INT | E29: 1 | F29: 0.0092592593 | G29: Demais causas de Atenuação | L29: =IFERROR(INDEX('BASE BI'!T:T,MATCH(A29,'BASE BI'!Y:Y,0)),"—") -> 0
A30: ITAPORANGA | C30: MA | D30: MA INT | E30: 1 | F30: 0.0092592593 | G30: Demais Causas de Rompimento | L30: =IFERROR(INDEX('BASE BI'!T:T,MATCH(A30,'BASE BI'!Y:Y,0)),"—") -> —
A31: OLINDA NOVA DO MARANHAO | C31: MA | D31: MA INT | E31: 1 | F31: 0.0092592593 | G31: Demais causas de Atenuação | L31: =IFERROR(INDEX('BASE BI'!T:T,MATCH(A31,'BASE BI'!Y:Y,0)),"—") -> 0
A32: PRESIDENTE DUTRA | C32: MA | D32: MA INT | E32: 1 | F32: 0.0092592593 | G32: Demais causas de Elétrica | L32: =IFERROR(INDEX('BASE BI'!T:T,MATCH(A32,'BASE BI'!Y:Y,0)),"—") -> 0
A33: SANTA INES | C33: MA | D33: MA INT | E33: 1 | F33: 0.0092592593 | G33: Sem Ação | L33: =IFERROR(INDEX('BASE BI'!T:T,MATCH(A33,'BASE BI'!Y:Y,0)),"—") -> ATEX NET TELECOMUNICAÇÕES LTDA
A34: SAO JOSE DE RIBAMAR | C34: MA | D34: MA CAP | E34: 1 | F34: 0.0092592593 | G34: Demais Causas de Rompimento | L34: =IFERROR(INDEX('BASE BI'!T:T,MATCH(A34,'BASE BI'!Y:Y,0)),"—") -> NMA SERVICOS DE TELECOMUNICACOES LTDA
A35: SIMOES
A36: TERESINA | C36: PI | D36: PI CAP | E36: 1 | F36: 0.0092592593 | G36: Demais Causas Configuração

Sheet REINCIDENTES
A1: 🔄 ANÁLISE DE CHAMADOS REINCIDENTES
A2: Referência: Coluna F (numplan/id serviço) + Coluna J (cliente_id) da BASE BI — Período INDEPENDENTE da aba Controle
A4: FILTRO DE PERÍODO
A5: Data Inicial: | B5: 46023 | C5: ← Edite a data inicial (célula B5)
A6: Data Final: | B6: 46139 | C6: ← Edite a data final (célula B6)
A7: Total chamados no período: | D7: =COUNTIFS('BASE BI'!N:N,">="&B5,'BASE BI'!N:N,"<="&B6+0.99999) -> 1188 | E7: Casos >24h: | G7: =COUNTIFS('BASE BI'!N:N,">="&B5,'BASE BI'!N:N,"<="&B6+0.99999,'BASE BI'!AH:AH,">"&24) -> 121 | H7: Casos ≤8h: | J7: =COUNTIFS('BASE BI'!N:N,">="&B5,'BASE BI'!N:N,"<="&B6+0.99999,'BASE BI'!AH:AH,"<="&8) -> 638 | K7: % Outlier >24h: | M7: =IFERROR(G7/D7,0) -> 0.10185185
A8: INDICADORES DE REINCIDÊNCIA NO PERÍODO
A9: ℹ️ Dados calculados sobre todo o banco. Para filtrar por período, ajuste as datas em B5 e B6 — os dados abaixo refletem ocorrências com 2+ chamados no cliente.
A10: RANKING DE CLIENTES REINCIDENTES NO PERÍODO | N10: REINCID. POR UF
A11: Rank | B11: ID Cliente | C11: Cód. Cliente | D11: Nome Cliente | E11: UF | F11: Cidade | G11: Ocorrências | H11: 1ª Abertura | I11: Última Abertura | J11: Causa Mais Freq. | N11: UF | O11: Ocorr.
A12: 1 | B12: 187 | C12: 216233 | D12: MUNICIPIO DE SAO LUIS SEMIT | E12: MA | F12: SAO LUIS | G12: 7 | H12: 19/01/2026 | I12: 07/03/2026 | J12: Demais Causas de Rompimento | N12: MA | O12: 562
A13: 2 | B13: 129 | C13: 218791 | D13: FUNDO MUNICIPAL DE SAUDE DE SAO LUIS MARANHAO | E13: MA | F13: SAO LUIS | G13: 7 | H13: 27/02/2026 | I13: 22/04/2026 | J13: Demais Causas de Rompimento | N13: PI | O13: 73
A14: 3 | B14: 426 | C14: 216233 | D14: MUNICIPIO DE SAO LUIS SEMIT | E14: MA | F14: SAO LUIS | G14: 7 | H14: 16/01/2026 | I14: 19/04/2026 | J14: Sem Ação | N14: PA | O14: 64
A15: 4 | B15: 422 | C15: 216233 | D15: MUNICIPIO DE SAO LUIS SEMIT | E15: MA | F15: SAO LUIS | G15: 7 | H15: 02/01/2026 | I15: 25/03/2026 | J15: Demais Causas de Rompimento | N15: AP | O15: 7
A16: 5 | B16: 11 | C16: 218297 | D16: J FEITOSA SILVA FILHO LOJAS SANTA MARIA | E16: MA | F16: SAO LUIS | G16: 7 | H16: 03/01/2026 | I16: 06/03/2026 | J16: Demais Causas de Rompimento | N16: AM | O16: 4
A17: 6 | B17: 1 | C17: 225005 | D17: CONDOMINIO DO SHOPPING METROPOLE ANANINDEUA CONDOM | E17: PA | F17: ANANINDEUA | G17: 7 | H17: 06/01/2026 | I17: 23/04/2026 | J17: Sem Ação
A18: 7 | B18: 299 | C18: 49495 | D18: FUNDO ESPECIAL DE MODERNIZACAO E REAPARELHAMENTO | E18: MA | F18: SAO LUIS | G18: 6 | H18: 07/01/2026 | I18: 23/04/2026 | J18: Rede Interna
A19: 8 | B19: 300 | C19: 49495 | D19: FUNDO ESPECIAL DE MODERNIZACAO E REAPARELHAMENTO | E19: MA | F19: ESPERANTINOPOLIS | G19: 6 | H19: 16/01/2026 | I19: 16/04/2026 | J19: Reset Equipamento
A20: 9 | B20: 367 | C20: 218787 | D20: MUNICIPIO DE SAO LUIS SEMED | E20: MA | F20: SAO LUIS | G20: 6 | H20: 06/01/2026 | I20: 30/03/2026 | J20: Demais Causas de Rompimento
A21: 10 | B21: 57 | C21: 218787 | D21: MUNICIPIO DE SAO LUIS SEMED | E21: MA | F21: SAO LUIS | G21: 5 | H21: 06/01/2026 | I21: 14/04/2026 | J21: Demais Causas de Rompimento
A22: 11 | B22: 340 | C22: 218787 | D22: MUNICIPIO DE SAO LUIS SEMED | E22: MA | F22: SAO LUIS | G22: 5 | H22: 12/01/2026 | I22: 27/03/2026 | J22: Demais Causas de Rompimento
A23: 12 | B23: 225 | C23: 218791 | D23: FUNDO MUNICIPAL DE SAUDE DE SAO LUIS MARANHAO | E23: MA | F23: SAO LUIS | G23: 5 | H23: 08/01/2026 | I23: 11/04/2026 | J23: Sem Ação
A24: 13 | B24: 1131 | C24: 83605 | D24: TIM S A TIM S A | E24: MA | F24: SAO LUIS | G24: 5 | H24: 01/02/2026 | I24: 23/04/2026 | J24: Demais Causas de Rompimento
A25: 14 | B25: 7 | C25: 219529 | D25: NORTE BRASIL NETWORK TELECOMUNICACOES LTDA NBN TEL | E25: AM | F25: PARINTINS | G25: 4 | H25: 05/02/2026 | I25: 16/04/2026 | J25: Sem Ação
A26: 15 | B26: 147 | C26: 212995 | D26: RAIA DROGASIL S A | E26: PA | F26: BENEVIDES | G26: 4 | H26: 27/02/2026 | I26: 22/04/2026 | J26: Demais Causas de Rompimento
A27: 16 | B27: 51 | C27: 216233 | D27: MUNICIPIO DE SAO LUIS SEMIT | E27: MA | F27: SAO LUIS | G27: 4 | H27: 13/02/2026 | I27: 22/04/2026 | J27: Demais causas de Atenuação
A28: 17 | B28: 16 | C28: 203391 | D28: SERVICO NACIONAL DE APRENDIZAGEM INDUSTRIAL SENAI | E28: PA | F28: BELEM | G28: 4 | H28: 10/01/2026 | I28: 26/04/2026 | J28: Demais causas de Elétrica
... A61: 50 | B61: 185 | C61: 216233 | D61: MUNICIPIO DE SAO LUIS SEMIT | E61: MA | F61: SAO LUIS | G61: 3 | H61: 18/02/2026 | I61: 23/04/2026 | J61: Demais Causas de Rompimento

Sheet EVOLUÇÃO
A1: 📈 EVOLUÇÃO MENSAL — INDICADORES B2B | Gráficos de Barras com Linha de Tendência
A3: MÊS | B3: TOTAL | C3: DENTRO 8H | D3: % ADER 8H | E3: META 8H | F3: OUTLIER >24H | G3: % OUTLIER | H3: TETO 24H
A4: Janeiro | B4: =COUNTIFS('BASE BI'!N:N,">="&DATE(2026,1,1),'BASE BI'!N:N,"<"&DATE(2026,1+1,1)) -> 309 | C4: =COUNTIFS('BASE BI'!N:N,">="&DATE(2026,1,1),'BASE BI'!N:N,"<"&DATE(2026,1+1,1),'BASE BI'!AH:AH,"<="&8) -> 180 | D4: =IFERROR(C4/B4,0) -> 0.58252427 | E4: =CONTROLE!I5 -> 0.85 | F4: =COUNTIFS('BASE BI'!N:N,">="&DATE(2026,1,1),'BASE BI'!N:N,"<"&DATE(2026,1+1,1),'BASE BI'!AH:AH,">"&24) -> 20 | G4: =IFERROR(F4/B4,0) -> 0.064724919 | H4: =CONTROLE!I6 -> 0.02
A5: Fevereiro | B5: =COUNTIFS('BASE BI'!N:N,">="&DATE(2026,2,1),'BASE BI'!N:N,"<"&DATE(2026,2+1,1)) -> 303 | C5: =COUNTIFS('BASE BI'!N:N,">="&DATE(2026,2,1),'BASE BI'!N:N,"<"&DATE(2026,2+1,1),'BASE BI'!AH:AH,"<="&8) -> 181 | D5: =IFERROR(C5/B5,0) -> 0.59735974 | E5: =CONTROLE!I5 -> 0.85 | F5: =COUNTIFS('BASE BI'!N:N,">="&DATE(2026,2,1),'BASE BI'!N:N,"<"&DATE(2026,2+1,1),'BASE BI'!AH:AH,">"&24) -> 17 | G5: =IFERROR(F5/B5,0) -> 0.056105611 | H5: =CONTROLE!I6 -> 0.02
A6: Março | B6: =COUNTIFS('BASE BI'!N:N,">="&DATE(2026,3,1),'BASE BI'!N:N,"<"&DATE(2026,3+1,1)) -> 275 | C6: =COUNTIFS('BASE BI'!N:N,">="&DATE(2026,3,1),'BASE BI'!N:N,"<"&DATE(2026,3+1,1),'BASE BI'!AH:AH,"<="&8) -> 156 | D6: =IFERROR(C6/B6,0) -> 0.56727273 | E6: =CONTROLE!I5 -> 0.85 | F6: =COUNTIFS('BASE BI'!N:N,">="&DATE(2026,3,1),'BASE BI'!N:N,"<"&DATE(2026,3+1,1),'BASE BI'!AH:AH,">"&24) -> 16 | G6: =IFERROR(F6/B6,0) -> 0.058181818 | H6: =CONTROLE!I6 -> 0.02
A7: Abril | B7: =COUNTIFS('BASE BI'!N:N,">="&DATE(2026,4,1),'BASE BI'!N:N,"<"&DATE(2026,4+1,1)) -> 339 | C7: =COUNTIFS('BASE BI'!N:N,">="&DATE(2026,4,1),'BASE BI'!N:N,"<"&DATE(2026,4+1,1),'BASE BI'!AH:AH,"<="&8) -> 142 | D7: =IFERROR(C7/B7,0) -> 0.41887906 | E7: =CONTROLE!I5 -> 0.85 | F7: =COUNTIFS('BASE BI'!N:N,">="&DATE(2026,4,1),'BASE BI'!N:N,"<"&DATE(2026,4+1,1),'BASE BI'!AH:AH,">"&24) -> 72 | G7: =IFERROR(F7/B7,0) -> 0.21238938 | H7: =CONTROLE!I6 -> 0.02
A8: Abril | B8: 303 | C8: 122 | D8: 0.4026 | E8: 0.85 | F8: 69 | G8: 0.2277 | H8: 0.02

Sheet FCA
A1: 📋 FCA — FATO / CAUSA / AÇÃO — TEXTO EXECUTIVO A NÍVEL DE DIRETORIA
A2: =" Referência: "&CONTROLE!D5&" | "&TEXT(CONTROLE!D7,"DD/MM/AAAA")&" a "&TEXT(CONTROLE!D8,"DD/MM/AAAA")&" | Elaborado por: Gerência CMO-Reparo" -> Referência: S16 | 13/04/2026 a 19/04/2026 | Elaborado por: Gerência CMO-Reparo
A4: ● B2B REPARO ≤8H — Meta: ≥85%
A5: FATO | C5: Na semana selecionada, o indicador B2B Reparo ≤8h registrou aderência abaixo da meta corporativa de 85%. Ver dados detalhados na aba RELATÓRIO EXECUTIVO e CONTROLE. Preencha abaixo a análise executiva para o período.
A6: CAUSA | C6: DESCREVA AQUI as principais causas identificadas para o desvio no indicador B2B Reparo ≤8h: Ex: Obras de readequação da postação pela concessionária Equatorial (COP30) em Belém-PA e Ananindeua-PA; Rompimentos de fibra em múltiplas localidades; Demora em tratativas com parceiros terceirizados (Online Telecom, Interling).
A7: AÇÃO | C7: DESCREVA AQUI as ações corretivas e preventivas planejadas: (1) Escalonamento junto à Equatorial para priorização de obras impactantes no SLA; (2) Revisão de SLA com parceiros Online e Interling; (3) Reforço de equipes de campo nas regiões PA CAP e MA CAP; (4) Mapeamento preventivo de redes críticas expostas a rompimentos.
A9: ● B2B OUTLIER >24H — Teto: ≤2% dos chamados
A10: FATO | C10: Na semana selecionada, o indicador B2B Outlier >24h registrou percentual de casos fora do prazo acima do teto de 2%. Ver dados detalhados na aba RELATÓRIO EXECUTIVO e CONTROLE. Preencha abaixo a análise executiva para o período.
A11: CAUSA | C11: DESCREVA AQUI as principais causas dos outliers >24h: Ex: Obras Equatorial/COP30 em Ananindeua-PA (maior concentração); Rompimentos de rede em Belém-PA; Demoras operacionais com parceiro Online em Moju-PA; Atenuações e rompimento em São Luís-MA.
A12: AÇÃO | C12: DESCREVA AQUI as ações corretivas: (1) Criação de sala de situação dedicada às obras COP30; (2) Acompanhamento diário de aging por gestor responsável; (3) Aplicação de penalidades contratuais a parceiros com SLA recorrentemente violado; (4) Apresentação de plano de recuperação à diretoria na semana seguinte.
A14: INDICADORES AUTOMÁTICOS DA SEMANA (referência)
A15: Semana | B15: =CONTROLE!D5 -> S16 | C15: Período | D15: =TEXT(CONTROLE!D7,"DD/MM/AAAA")&" a "&TEXT(CONTROLE!D8,"DD/MM/AAAA") -> 13/04/2026 a 19/04/2026 | E15: Total Chamados | F15: =CONTROLE!D9 -> 106 | G15: B2B ≤8h | H15: =TEXT(CONTROLE!B13,"0.0%")&" (meta 85%)" -> 40% (meta 85%) | I15: B2B Outlier >24h | J15: =TEXT(CONTROLE!E13,"0.0%")&" (teto 2%)" -> 25% (teto 2%)

Sheet DASHBOARD
A1: 🎯 DASHBOARD EXECUTIVO B2B — VISÃO GERAL SEMANAL
