Workbook

Sheet BASE
A1: ID Ticket | B1: Cliente | C1: Departamento | D1: Tipo de Atendimento | E1: Assunto | F1: Abertura do Ticket | G1: Tempo | H1: Status | I1: Substatus | J1: Ticket Bdesk | K1: Cidade | L1: UF | M1: REGIÃO | N1: MOP/EPS (Regra) | O1: SLA (h) | P1: SLA Formatado | Q1: Faixa SLA | R1: Status SLA | S1: AUX_SEQ_MOP | T1: AUX_COD_MOP | U1: AUX_CHAVE_NUM | V1: Link Atrix
A2: 15052026-24054 | B2: VENTOS DE SANTO ONOFRE | C2: CMO - Reparo | D2: REPARO | E2: VENTOS DE SANTO ONOFRE ENERGIAS RENOVAVEIS S A | INDISPONIBILIDADE | SYS/IPD/209717/1 | F2: 46157.927 | G2: 18 | H2: Em Espera | I2: AGUARDANDO LIBERAÇÃO DE ACESSO | K2: SIMOES | L2: PI | M2: =IF($A2="","",IF($L2="MA",IF(OR(UPPER($K2)="SAO LUIS",UPPER($K2)="SÃO LUIS",UPPER($K2)="PACO DO LUMIAR",UPPER($K2)="PAÇO DO LUMIAR",UPPER($K2)="SAO JOSE DE RIBAMAR",UPPER($K2)="SÃO JOSÉ DE RIBAMAR"),"MA CAP","MA INT"),IF($L2="PA",IF(OR(UPPER($K2)="BELEM",UPPER($K2)="BELÉM",UPPER($K2)="ANANINDEUA"),"PA CAP","PA INT"),IF($L2="PI",IF(UPPER($K2)="TERESINA","PI CAP","PI INT"),IF($L2="AM","AM INT",IF($L2="AP","AP","OUTROS")))))) -> PI INT | N2: =IF($A2="","",IF($M2="PI CAP","GIGA+ PI",IF($M2="PI INT","GIGA+ PI",IF($M2="MA CAP","SLN MA",IF($M2="MA INT","GIGA+ MA",IF($M2="PA CAP","SLN PA",IF($M2="PA INT","SLN PA",IF($M2="AM INT","ADX",IF($M2="AP","ADX","OUTROS"))))))))) -> GIGA+ PI | O2: =IF(F2="","",IF(INT(F2)=INT(NOW()),IF(NETWORKDAYS.INTL(F2,F2,1,FERIADOS!$A$2:$A$50)=0,0,MAX(0,(MIN(NOW(),INT(NOW())+18/24)-MAX(F2,INT(F2)+8/24)))*24),MAX(0,(INT(F2)+18/24-MAX(F2,INT(F2)+8/24)))*24*NETWORKDAYS.INTL(F2,F2,1,FERIADOS!$A$2:$A$50)+MAX(0,NETWORKDAYS.INTL(F2+1,NOW()-1,1,FERIADOS!$A$2:$A$50))*10+MAX(0,(MIN(NOW(),INT(NOW())+18/24)-(INT(NOW())+8/24)))*24*NETWORKDAYS.INTL(NOW(),NOW(),1,FERIADOS!$A$2:$A$50))) -> 120 | P2: =IF($A2="","",IF(OR(O2="",O2=0),"00h 00m",TEXT(INT(O2),"00") & "h " & TEXT(INT((O2-INT(O2))*60),"00") & "m")) -> 120h 00m | Q2: =IF($A2="","",IF(OR(O2="",O2<=4),"🔵 Até 4h",IF(O2<=8,"🟢 Entre 4h e 8h",IF(O2<=12,"🟡 Entre 8h e 12h",IF(O2<=24,"🟠 Entre 12h e 24h","🔴 Maior que 24h"))))) -> 🔴 Maior que 24h | R2: =IF($A2="","",IF(OR(O2="",O2<=8),"NO PRAZO","FORA DO PRAZO")) -> FORA DO PRAZO | S2: =IF($A2="","",COUNTIF($N$2:N2,$N2)) -> 1 | T2: =IF($A2="","",IF($N2="SLN MA",1,IF($N2="GIGA+ MA",2,IF($N2="GIGA+ PI",3,IF($N2="SLN PA",4,IF($N2="ADX",5,6)))))) -> 3 | U2: =IF($A2="","",$T2*10000+$S2) -> 30001 | V2: https://atrix.mobtelecom.com.br/controle/addonmodules.php?module=helpdesk#/app/ticket/5981213
A3: 27052026-71809 | B3: SERVICO NACIONAL DE APRENDIZAGEM COMERCIAL SENAC | C3: CMO - Reparo | D3: REPARO | E3: SERVICO NACIONAL DE APRENDIZAGEM COMERCIAL | INDISPONIBILIDADE | CXS/IPD/201697/7 | F3: 46169.68 | G3: 6 | H3: Em Espera | I3: PENDENTE AGENDAMENTO | K3: CAXIAS | L3: MA | M3: =IF($A3="","",IF($L3="MA",IF(OR(UPPER($K3)="SAO LUIS",UPPER($K3)="SÃO LUIS",UPPER($K3)="PACO DO LUMIAR",UPPER($K3)="PAÇO DO LUMIAR",UPPER($K3)="SAO JOSE DE RIBAMAR",UPPER($K3)="SÃO JOSÉ DE RIBAMAR"),"MA CAP","MA INT"),IF($L3="PA",IF(OR(UPPER($K3)="BELEM",UPPER($K3)="BELÉM",UPPER($K3)="ANANINDEUA"),"PA CAP","PA INT"),IF($L3="PI",IF(UPPER($K3)="TERESINA","PI CAP","PI INT"),IF($L3="AM","AM INT",IF($L3="AP","AP","OUTROS")))))) -> MA INT | N3: =IF($A3="","",IF($M3="PI CAP","GIGA+ PI",IF($M3="PI INT","GIGA+ PI",IF($M3="MA CAP","SLN MA",IF($M3="MA INT","GIGA+ MA",IF($M3="PA CAP","SLN PA",IF($M3="PA INT","SLN PA",IF($M3="AM INT","ADX",IF($M3="AP","ADX","OUTROS"))))))))) -> GIGA+ MA | O3: =IF(F3="","",IF(INT(F3)=INT(NOW()),IF(NETWORKDAYS.INTL(F3,F3,1,FERIADOS!$A$2:$A$50)=0,0,MAX(0,(MIN(NOW(),INT(NOW())+18/24)-MAX(F3,INT(F3)+8/24)))*24),MAX(0,(INT(F3)+18/24-MAX(F3,INT(F3)+8/24)))*24*NETWORKDAYS.INTL(F3,F3,1,FERIADOS!$A$2:$A$50)+MAX(0,NETWORKDAYS.INTL(F3+1,NOW()-1,1,FERIADOS!$A$2:$A$50))*10+MAX(0,(MIN(NOW(),INT(NOW())+18/24)-(INT(NOW())+8/24)))*24*NETWORKDAYS.INTL(NOW(),NOW(),1,FERIADOS!$A$2:$A$50))) -> 41.688889 | P3: =IF($A3="","",IF(OR(O3="",O3=0),"00h 00m",TEXT(INT(O3),"00") & "h " & TEXT(INT((O3-INT(O3))*60),"00") & "m")) -> 41h 41m | Q3: =IF($A3="","",IF(OR(O3="",O3<=4),"🔵 Até 4h",IF(O3<=8,"🟢 Entre 4h e 8h",IF(O3<=12,"🟡 Entre 8h e 12h",IF(O3<=24,"🟠 Entre 12h e 24h","🔴 Maior que 24h"))))) -> 🔴 Maior que 24h | R3: =IF($A3="","",IF(OR(O3="",O3<=8),"NO PRAZO","FORA DO PRAZO")) -> FORA DO PRAZO | S3: =IF($A3="","",COUNTIF($N$2:N3,$N3)) -> 1 | T3: =IF($A3="","",IF($N3="SLN MA",1,IF($N3="GIGA+ MA",2,IF($N3="GIGA+ PI",3,IF($N3="SLN PA",4,IF($N3="ADX",5,6)))))) -> 2 | U3: =IF($A3="","",$T3*10000+$S3) -> 20001 | V3: https://atrix.mobtelecom.com.br/controle/addonmodules.php?module=helpdesk#/app/ticket/5981391
A4: 28052026-26217 | B4: SERVICO SOCIAL DO TRANSPORTE SEST SAO LUIS | C4: CMO - Reparo | D4: EQUIPAMENTO | E4: #25052026-72931 - SERVICO SOCIAL DO TRANSPORTE SEST SAO LUIS | PERFORMACE | SLS/IPD/227969/1 | F4: 46170.612 | G4: 5 | H4: Em Espera | I4: PENDENTE AGENDAMENTO | K4: SAO LUIS | L4: MA | M4: =IF($A4="","",IF($L4="MA",IF(OR(UPPER($K4)="SAO LUIS",UPPER($K4)="SÃO LUIS",UPPER($K4)="PACO DO LUMIAR",UPPER($K4)="PAÇO DO LUMIAR",UPPER($K4)="SAO JOSE DE RIBAMAR",UPPER($K4)="SÃO JOSÉ DE RIBAMAR"),"MA CAP","MA INT"),IF($L4="PA",IF(OR(UPPER($K4)="BELEM",UPPER($K4)="BELÉM",UPPER($K4)="ANANINDEUA"),"PA CAP","PA INT"),IF($L4="PI",IF(UPPER($K4)="TERESINA","PI CAP","PI INT"),IF($L4="AM","AM INT",IF($L4="AP","AP","OUTROS")))))) -> MA CAP | N4: =IF($A4="","",IF($M4="PI CAP","GIGA+ PI",IF($M4="PI INT","GIGA+ PI",IF($M4="MA CAP","SLN MA",IF($M4="MA INT","GIGA+ MA",IF($M4="PA CAP","SLN PA",IF($M4="PA INT","SLN PA",IF($M4="AM INT","ADX",IF($M4="AP","ADX","OUTROS"))))))))) -> SLN MA | O4: =IF(F4="","",IF(INT(F4)=INT(NOW()),IF(NETWORKDAYS.INTL(F4,F4,1,FERIADOS!$A$2:$A$50)=0,0,MAX(0,(MIN(NOW(),INT(NOW())+18/24)-MAX(F4,INT(F4)+8/24)))*24),MAX(0,(INT(F4)+18/24-MAX(F4,INT(F4)+8/24)))*24*NETWORKDAYS.INTL(F4,F4,1,FERIADOS!$A$2:$A$50)+MAX(0,NETWORKDAYS.INTL(F4+1,NOW()-1,1,FERIADOS!$A$2:$A$50))*10+MAX(0,(MIN(NOW(),INT(NOW())+18/24)-(INT(NOW())+8/24)))*24*NETWORKDAYS.INTL(NOW(),NOW(),1,FERIADOS!$A$2:$A$50))) -> 33.301389 | P4: =IF($A4="","",IF(OR(O4="",O4=0),"00h 00m",TEXT(INT(O4),"00") & "h " & TEXT(INT((O4-INT(O4))*60),"00") & "m")) -> 33h 18m | Q4: =IF($A4="","",IF(OR(O4="",O4<=4),"🔵 Até 4h",IF(O4<=8,"🟢 Entre 4h e 8h",IF(O4<=12,"🟡 Entre 8h e 12h",IF(O4<=24,"🟠 Entre 12h e 24h","🔴 Maior que 24h"))))) -> 🔴 Maior que 24h | R4: =IF($A4="","",IF(OR(O4="",O4<=8),"NO PRAZO","FORA DO PRAZO")) -> FORA DO PRAZO | S4: =IF($A4="","",COUNTIF($N$2:N4,$N4)) -> 1 | T4: =IF($A4="","",IF($N4="SLN MA",1,IF($N4="GIGA+ MA",2,IF($N4="GIGA+ PI",3,IF($N4="SLN PA",4,IF($N4="ADX",5,6)))))) -> 1 | U4: =IF($A4="","",$T4*10000+$S4) -> 10001 | V4: https://atrix.mobtelecom.com.br/controle/addonmodules.php?module=helpdesk#/app/ticket/5981465
A5: 29052026-25755 | B5: MUNICIPIO DE SAO LUIS | C5: CMO - Reparo | D5: REPARO | E5: Atendimento para: RESIDENCIA INCLUSIVA - VLAN-3784 SLS-216233-00144 | F5: 46171.598 | G5: 4 | H5: Em Espera | I5: PENDENTE AGENDAMENTO | K5: SAO LUIS | L5: MA | M5: =IF($A5="","",IF($L5="MA",IF(OR(UPPER($K5)="SAO LUIS",UPPER($K5)="SÃO LUIS",UPPER($K5)="PACO DO LUMIAR",UPPER($K5)="PAÇO DO LUMIAR",UPPER($K5)="SAO JOSE DE RIBAMAR",UPPER($K5)="SÃO JOSÉ DE RIBAMAR"),"MA CAP","MA INT"),IF($L5="PA",IF(OR(UPPER($K5)="BELEM",UPPER($K5)="BELÉM",UPPER($K5)="ANANINDEUA"),"PA CAP","PA INT"),IF($L5="PI",IF(UPPER($K5)="TERESINA","PI CAP","PI INT"),IF($L5="AM","AM INT",IF($L5="AP","AP","OUTROS")))))) -> MA CAP | N5: =IF($A5="","",IF($M5="PI CAP","GIGA+ PI",IF($M5="PI INT","GIGA+ PI",IF($M5="MA CAP","SLN MA",IF($M5="MA INT","GIGA+ MA",IF($M5="PA CAP","SLN PA",IF($M5="PA INT","SLN PA",IF($M5="AM INT","ADX",IF($M5="AP","ADX","OUTROS"))))))))) -> SLN MA | O5: =IF(F5="","",IF(INT(F5)=INT(NOW()),IF(NETWORKDAYS.INTL(F5,F5,1,FERIADOS!$A$2:$A$50)=0,0,MAX(0,(MIN(NOW(),INT(NOW())+18/24)-MAX(F5,INT(F5)+8/24)))*24),MAX(0,(INT(F5)+18/24-MAX(F5,INT(F5)+8/24)))*24*NETWORKDAYS.INTL(F5,F5,1,FERIADOS!$A$2:$A$50)+MAX(0,NETWORKDAYS.INTL(F5+1,NOW()-1,1,FERIADOS!$A$2:$A$50))*10+MAX(0,(MIN(NOW(),INT(NOW())+18/24)-(INT(NOW())+8/24)))*24*NETWORKDAYS.INTL(NOW(),NOW(),1,FERIADOS!$A$2:$A$50))) -> 23.651389 | P5: =IF($A5="","",IF(OR(O5="",O5=0),"00h 00m",TEXT(INT(O5),"00") & "h " & TEXT(INT((O5-INT(O5))*60),"00") & "m")) -> 23h 39m | Q5: =IF($A5="","",IF(OR(O5="",O5<=4),"🔵 Até 4h",IF(O5<=8,"🟢 Entre 4h e 8h",IF(O5<=12,"🟡 Entre 8h e 12h",IF(O5<=24,"🟠 Entre 12h e 24h","🔴 Maior que 24h"))))) -> 🟠 Entre 12h e 24h | R5: =IF($A5="","",IF(OR(O5="",O5<=8),"NO PRAZO","FORA DO PRAZO")) -> FORA DO PRAZO | S5: =IF($A5="","",COUNTIF($N$2:N5,$N5)) -> 2 | T5: =IF($A5="","",IF($N5="SLN MA",1,IF($N5="GIGA+ MA",2,IF($N5="GIGA+ PI",3,IF($N5="SLN PA",4,IF($N5="ADX",5,6)))))) -> 1 | U5: =IF($A5="","",$T5*10000+$S5) -> 10002 | V5: https://atrix.mobtelecom.com.br/controle/addonmodules.php?module=helpdesk#/app/ticket/5981503
A6: 30052026-59919 | B6: TRIBUNAL REGIONAL DO TRABALHO DA 16 REGIAO | C6: CMO - Reparo | D6: REPARO | E6: ALERTA: CLI | TRT16.SLS.SAO.LUIS.SLAVE.RB.IPD.202555.39 - FALHA | F6: 46172.542 | G6: 3 | H6: Em Espera | I6: PENDENTE AGENDAMENTO | K6: SAO LUIS | L6: MA | M6: =IF($A6="","",IF($L6="MA",IF(OR(UPPER($K6)="SAO LUIS",UPPER($K6)="SÃO LUIS",UPPER($K6)="PACO DO LUMIAR",UPPER($K6)="PAÇO DO LUMIAR",UPPER($K6)="SAO JOSE DE RIBAMAR",UPPER($K6)="SÃO JOSÉ DE RIBAMAR"),"MA CAP","MA INT"),IF($L6="PA",IF(OR(UPPER($K6)="BELEM",UPPER($K6)="BELÉM",UPPER($K6)="ANANINDEUA"),"PA CAP","PA INT"),IF($L6="PI",IF(UPPER($K6)="TERESINA","PI CAP","PI INT"),IF($L6="AM","AM INT",IF($L6="AP","AP","OUTROS")))))) -> MA CAP | N6: =IF($A6="","",IF($M6="PI CAP","GIGA+ PI",IF($M6="PI INT","GIGA+ PI",IF($M6="MA CAP","SLN MA",IF($M6="MA INT","GIGA+ MA",IF($M6="PA CAP","SLN PA",IF($M6="PA INT","SLN PA",IF($M6="AM INT","ADX",IF($M6="AP","ADX","OUTROS"))))))))) -> SLN MA | O6: =IF(F6="","",IF(INT(F6)=INT(NOW()),IF(NETWORKDAYS.INTL(F6,F6,1,FERIADOS!$A$2:$A$50)=0,0,MAX(0,(MIN(NOW(),INT(NOW())+18/24)-MAX(F6,INT(F6)+8/24)))*24),MAX(0,(INT(F6)+18/24-MAX(F6,INT(F6)+8/24)))*24*NETWORKDAYS.INTL(F6,F6,1,FERIADOS!$A$2:$A$50)+MAX(0,NETWORKDAYS.INTL(F6+1,NOW()-1,1,FERIADOS!$A$2:$A$50))*10+MAX(0,(MIN(NOW(),INT(NOW())+18/24)-(INT(NOW())+8/24)))*24*NETWORKDAYS.INTL(NOW(),NOW(),1,FERIADOS!$A$2:$A$50))) -> 20 | P6: =IF($A6="","",IF(OR(O6="",O6=0),"00h 00m",TEXT(INT(O6),"00") & "h " & TEXT(INT((O6-INT(O6))*60),"00") & "m")) -> 20h 00m | Q6: =IF($A6="","",IF(OR(O6="",O6<=4),"🔵 Até 4h",IF(O6<=8,"🟢 Entre 4h e 8h",IF(O6<=12,"🟡 Entre 8h e 12h",IF(O6<=24,"🟠 Entre 12h e 24h","🔴 Maior que 24h"))))) -> 🟠 Entre 12h e 24h | R6: =IF($A6="","",IF(OR(O6="",O6<=8),"NO PRAZO","FORA DO PRAZO")) -> FORA DO PRAZO | S6: =IF($A6="","",COUNTIF($N$2:N6,$N6)) -> 3 | T6: =IF($A6="","",IF($N6="SLN MA",1,IF($N6="GIGA+ MA",2,IF($N6="GIGA+ PI",3,IF($N6="SLN PA",4,IF($N6="ADX",5,6)))))) -> 1 | U6: =IF($A6="","",$T6*10000+$S6) -> 10003 | V6: https://atrix.mobtelecom.com.br/controle/addonmodules.php?module=helpdesk#/app/ticket/5981589
A7: 31052026-18085 | B7: MUNICIPIO DE SAO LUIS | C7: CMO - Reparo | D7: REPARO | E7: Atendimento para: UEB ENS FUND JOSEFINA SERRAO - SLS-218787-00361 | F7: 46173.806 | G7: 2 | H7: Em Espera | I7: PENDENTE AGENDAMENTO | K7: SAO LUIS | L7: MA | M7: =IF($A7="","",IF($L7="MA",IF(OR(UPPER($K7)="SAO LUIS",UPPER($K7)="SÃO LUIS",UPPER($K7)="PACO DO LUMIAR",UPPER($K7)="PAÇO DO LUMIAR",UPPER($K7)="SAO JOSE DE RIBAMAR",UPPER($K7)="SÃO JOSÉ DE RIBAMAR"),"MA CAP","MA INT"),IF($L7="PA",IF(OR(UPPER($K7)="BELEM",UPPER($K7)="BELÉM",UPPER($K7)="ANANINDEUA"),"PA CAP","PA INT"),IF($L7="PI",IF(UPPER($K7)="TERESINA","PI CAP","PI INT"),IF($L7="AM","AM INT",IF($L7="AP","AP","OUTROS")))))) -> MA CAP | N7: =IF($A7="","",IF($M7="PI CAP","GIGA+ PI",IF($M7="PI INT","GIGA+ PI",IF($M7="MA CAP","SLN MA",IF($M7="MA INT","GIGA+ MA",IF($M7="PA CAP","SLN PA",IF($M7="PA INT","SLN PA",IF($M7="AM INT","ADX",IF($M7="AP","ADX","OUTROS"))))))))) -> SLN MA | O7: =IF(F7="","",IF(INT(F7)=INT(NOW()),IF(NETWORKDAYS.INTL(F7,F7,1,FERIADOS!$A$2:$A$50)=0,0,MAX(0,(MIN(NOW(),INT(NOW())+18/24)-MAX(F7,INT(F7)+8/24)))*24),MAX(0,(INT(F7)+18/24-MAX(F7,INT(F7)+8/24)))*24*NETWORKDAYS.INTL(F7,F7,1,FERIADOS!$A$2:$A$50)+MAX(0,NETWORKDAYS.INTL(F7+1,NOW()-1,1,FERIADOS!$A$2:$A$50))*10+MAX(0,(MIN(NOW(),INT(NOW())+18/24)-(INT(NOW())+8/24)))*24*NETWORKDAYS.INTL(NOW(),NOW(),1,FERIADOS!$A$2:$A$50))) -> 20 | P7: =IF($A7="","",IF(OR(O7="",O7=0),"00h 00m",TEXT(INT(O7),"00") & "h " & TEXT(INT((O7-INT(O7))*60),"00") & "m")) -> 20h 00m | Q7: =IF($A7="","",IF(OR(O7="",O7<=4),"🔵 Até 4h",IF(O7<=8,"🟢 Entre 4h e 8h",IF(O7<=12,"🟡 Entre 8h e 12h",IF(O7<=24,"🟠 Entre 12h e 24h","🔴 Maior que 24h"))))) -> 🟠 Entre 12h e 24h | R7: =IF($A7="","",IF(OR(O7="",O7<=8),"NO PRAZO","FORA DO PRAZO")) -> FORA DO PRAZO | S7: =IF($A7="","",COUNTIF($N$2:N7,$N7)) -> 4 | T7: =IF($A7="","",IF($N7="SLN MA",1,IF($N7="GIGA+ MA",2,IF($N7="GIGA+ PI",3,IF($N7="SLN PA",4,IF($N7="ADX",5,6)))))) -> 1 | U7: =IF($A7="","",$T7*10000+$S7) -> 10004
A8: 31052026-18776 | B8: MUNICIPIO DE SAO LUIS | C8: CMO - Reparo | D8: REPARO | E8: Atendimento para: CREAS COROADINHO - VLAN 3737 SLS-216233-00150 | F8: 46173.209 | G8: 2 | H8: Em Espera | I8: PENDENTE VALIDAÇÃO | K8: SAO LUIS | L8: MA | M8: =IF($A8="","",IF($L8="MA",IF(OR(UPPER($K8)="SAO LUIS",UPPER($K8)="SÃO LUIS",UPPER($K8)="PACO DO LUMIAR",UPPER($K8)="PAÇO DO LUMIAR",UPPER($K8)="SAO JOSE DE RIBAMAR",UPPER($K8)="SÃO JOSÉ DE RIBAMAR"),"MA CAP","MA INT"),IF($L8="PA",IF(OR(UPPER($K8)="BELEM",UPPER($K8)="BELÉM",UPPER($K8)="ANANINDEUA"),"PA CAP","PA INT"),IF($L8="PI",IF(UPPER($K8)="TERESINA","PI CAP","PI INT"),IF($L8="AM","AM INT",IF($L8="AP","AP","OUTROS")))))) -> MA CAP | N8: =IF($A8="","",IF($M8="PI CAP","GIGA+ PI",IF($M8="PI INT","GIGA+ PI",IF($M8="MA CAP","SLN MA",IF($M8="MA INT","GIGA+ MA",IF($M8="PA CAP","SLN PA",IF($M8="PA INT","SLN PA",IF($M8="AM INT","ADX",IF($M8="AP","ADX","OUTROS"))))))))) -> SLN MA | O8: =IF(F8="","",IF(INT(F8)=INT(NOW()),IF(NETWORKDAYS.INTL(F8,F8,1,FERIADOS!$A$2:$A$50)=0,0,MAX(0,(MIN(NOW(),INT(NOW())+18/24)-MAX(F8,INT(F8)+8/24)))*24),MAX(0,(INT(F8)+18/24-MAX(F8,INT(F8)+8/24)))*24*NETWORKDAYS.INTL(F8,F8,1,FERIADOS!$A$2:$A$50)+MAX(0,NETWORKDAYS.INTL(F8+1,NOW()-1,1,FERIADOS!$A$2:$A$50))*10+MAX(0,(MIN(NOW(),INT(NOW())+18/24)-(INT(NOW())+8/24)))*24*NETWORKDAYS.INTL(NOW(),NOW(),1,FERIADOS!$A$2:$A$50))) -> 20 | P8: =IF($A8="","",IF(OR(O8="",O8=0),"00h 00m",TEXT(INT(O8),"00") & "h " & TEXT(INT((O8-INT(O8))*60),"00") & "m")) -> 20h 00m | Q8: =IF($A8="","",IF(OR(O8="",O8<=4),"🔵 Até 4h",IF(O8<=8,"🟢 Entre 4h e 8h",IF(O8<=12,"🟡 Entre 8h e 12h",IF(O8<=24,"🟠 Entre 12h e 24h","🔴 Maior que 24h"))))) -> 🟠 Entre 12h e 24h | R8: =IF($A8="","",IF(OR(O8="",O8<=8),"NO PRAZO","FORA DO PRAZO")) -> FORA DO PRAZO | S8: =IF($A8="","",COUNTIF($N$2:N8,$N8)) -> 5 | T8: =IF($A8="","",IF($N8="SLN MA",1,IF($N8="GIGA+ MA",2,IF($N8="GIGA+ PI",3,IF($N8="SLN PA",4,IF($N8="ADX",5,6)))))) -> 1 | U8: =IF($A8="","",$T8*10000+$S8) -> 10005 | V8: https://atrix.mobtelecom.com.br/controle/addonmodules.php?module=helpdesk#/app/ticket/5981837
A9: 31052026-98262 | B9: MUNICIPIO DE SAO LUIS | C9: CMO - Reparo | D9: REPARO | E9: Atendimento para: CRAS COROADINHO - VLAN 3736 SLS-216233-00392 | F9: 46173.209 | G9: 2 | H9: Em Espera | I9: PENDENTE AGENDAMENTO | K9: SAO LUIS | L9: MA | M9: =IF($A9="","",IF($L9="MA",IF(OR(UPPER($K9)="SAO LUIS",UPPER($K9)="SÃO LUIS",UPPER($K9)="PACO DO LUMIAR",UPPER($K9)="PAÇO DO LUMIAR",UPPER($K9)="SAO JOSE DE RIBAMAR",UPPER($K9)="SÃO JOSÉ DE RIBAMAR"),"MA CAP","MA INT"),IF($L9="PA",IF(OR(UPPER($K9)="BELEM",UPPER($K9)="BELÉM",UPPER($K9)="ANANINDEUA"),"PA CAP","PA INT"),IF($L9="PI",IF(UPPER($K9)="TERESINA","PI CAP","PI INT"),IF($L9="AM","AM INT",IF($L9="AP","AP","OUTROS")))))) -> MA CAP | N9: =IF($A9="","",IF($M9="PI CAP","GIGA+ PI",IF($M9="PI INT","GIGA+ PI",IF($M9="MA CAP","SLN MA",IF($M9="MA INT","GIGA+ MA",IF($M9="PA CAP","SLN PA",IF($M9="PA INT","SLN PA",IF($M9="AM INT","ADX",IF($M9="AP","ADX","OUTROS"))))))))) -> SLN MA | O9: =IF(F9="","",IF(INT(F9)=INT(NOW()),IF(NETWORKDAYS.INTL(F9,F9,1,FERIADOS!$A$2:$A$50)=0,0,MAX(0,(MIN(NOW(),INT(NOW())+18/24)-MAX(F9,INT(F9)+8/24)))*24),MAX(0,(INT(F9)+18/24-MAX(F9,INT(F9)+8/24)))*24*NETWORKDAYS.INTL(F9,F9,1,FERIADOS!$A$2:$A$50)+MAX(0,NETWORKDAYS.INTL(F9+1,NOW()-1,1,FERIADOS!$A$2:$A$50))*10+MAX(0,(MIN(NOW(),INT(NOW())+18/24)-(INT(NOW())+8/24)))*24*NETWORKDAYS.INTL(NOW(),NOW(),1,FERIADOS!$A$2:$A$50))) -> 20 | P9: =IF($A9="","",IF(OR(O9="",O9=0),"00h 00m",TEXT(INT(O9),"00") & "h " & TEXT(INT((O9-INT(O9))*60),"00") & "m")) -> 20h 00m | Q9: =IF($A9="","",IF(OR(O9="",O9<=4),"🔵 Até 4h",IF(O9<=8,"🟢 Entre 4h e 8h",IF(O9<=12,"🟡 Entre 8h e 12h",IF(O9<=24,"🟠 Entre 12h e 24h","🔴 Maior que 24h"))))) -> 🟠 Entre 12h e 24h | R9: =IF($A9="","",IF(OR(O9="",O9<=8),"NO PRAZO","FORA DO PRAZO")) -> FORA DO PRAZO | S9: =IF($A9="","",COUNTIF($N$2:N9,$N9)) -> 6 | T9: =IF($A9="","",IF($N9="SLN MA",1,IF($N9="GIGA+ MA",2,IF($N9="GIGA+ PI",3,IF($N9="SLN PA",4,IF($N9="ADX",5,6)))))) -> 1 | U9: =IF($A9="","",$T9*10000+$S9) -> 10006 | V9: https://atrix.mobtelecom.com.br/controle/addonmodules.php?module=helpdesk#/app/ticket/5981747
A10: 31052026-95072 | B10: FUNDO MUNICIPAL DE SAUDE DE SAO LUIS MARANHAO | C10: CMO - Reparo | D10: REPARO | E10: Atendimento para: CS Dr. ANTONIO GUANARE - VLAN 3622 SLS-216233-00120 | F10: 46173.209 | G10: 2 | H10: Em Espera | I10: PENDENTE VALIDAÇÃO | K10: SAO LUIS | L10: MA | M10: =IF($A10="","",IF($L10="MA",IF(OR(UPPER($K10)="SAO LUIS",UPPER($K10)="SÃO LUIS",UPPER($K10)="PACO DO LUMIAR",UPPER($K10)="PAÇO DO LUMIAR",UPPER($K10)="SAO JOSE DE RIBAMAR",UPPER($K10)="SÃO JOSÉ DE RIBAMAR"),"MA CAP","MA INT"),IF($L10="PA",IF(OR(UPPER($K10)="BELEM",UPPER($K10)="BELÉM",UPPER($K10)="ANANINDEUA"),"PA CAP","PA INT"),IF($L10="PI",IF(UPPER($K10)="TERESINA","PI CAP","PI INT"),IF($L10="AM","AM INT",IF($L10="AP","AP","OUTROS")))))) -> MA CAP | N10: =IF($A10="","",IF($M10="PI CAP","GIGA+ PI",IF($M10="PI INT","GIGA+ PI",IF($M10="MA CAP","SLN MA",IF($M10="MA INT","GIGA+ MA",IF($M10="PA CAP","SLN PA",IF($M10="PA INT","SLN PA",IF($M10="AM INT","ADX",IF($M10="AP","ADX","OUTROS"))))))))) -> SLN MA | O10: =IF(F10="","",IF(INT(F10)=INT(NOW()),IF(NETWORKDAYS.INTL(F10,F10,1,FERIADOS!$A$2:$A$50)=0,0,MAX(0,(MIN(NOW(),INT(NOW())+18/24)-MAX(F10,INT(F10)+8/24)))*24),MAX(0,(INT(F10)+18/24-MAX(F10,INT(F10)+8/24)))*24*NETWORKDAYS.INTL(F10,F10,1,FERIADOS!$A$2:$A$50)+MAX(0,NETWORKDAYS.INTL(F10+1,NOW()-1,1,FERIADOS!$A$2:$A$50))*10+MAX(0,(MIN(NOW(),INT(NOW())+18/24)-(INT(NOW())+8/24)))*24*NETWORKDAYS.INTL(NOW(),NOW(),1,FERIADOS!$A$2:$A$50))) -> 20 | P10: =IF($A10="","",IF(OR(O10="",O10=0),"00h 00m",TEXT(INT(O10),"00") & "h " & TEXT(INT((O10-INT(O10))*60),"00") & "m")) -> 20h 00m | Q10: =IF($A10="","",IF(OR(O10="",O10<=4),"🔵 Até 4h",IF(O10<=8,"🟢 Entre 4h e 8h",IF(O10<=12,"🟡 Entre 8h e 12h",IF(O10<=24,"🟠 Entre 12h e 24h","🔴 Maior que 24h"))))) -> 🟠 Entre 12h e 24h | R10: =IF($A10="","",IF(OR(O10="",O10<=8),"NO PRAZO","FORA DO PRAZO")) -> FORA DO PRAZO | S10: =IF($A10="","",COUNTIF($N$2:N10,$N10)) -> 7 | T10: =IF($A10="","",IF($N10="SLN MA",1,IF($N10="GIGA+ MA",2,IF($N10="GIGA+ PI",3,IF($N10="SLN PA",4,IF($N10="ADX",5,6)))))) -> 1 | U10: =IF($A10="","",$T10*10000+$S10) -> 10007 | V10: https://atrix.mobtelecom.com.br/controle/addonmodules.php?module=helpdesk#/app/ticket/5980007
A11: 01062026-79927 | B11: MUNICIPIO DE SAO LUIS | C11: CMO - Reparo | D11: REPARO | E11: Atendimento para: SEMFAZ CENTRO - SLS-216233-00020 | F11: 46174.959 | G11: 1 | H11: Em Espera | I11: PENDENTE AGENDAMENTO | K11: SAO LUIS | L11: MA | M11: =IF($A11="","",IF($L11="MA",IF(OR(UPPER($K11)="SAO LUIS",UPPER($K11)="SÃO LUIS",UPPER($K11)="PACO DO LUMIAR",UPPER($K11)="PAÇO DO LUMIAR",UPPER($K11)="SAO JOSE DE RIBAMAR",UPPER($K11)="SÃO JOSÉ DE RIBAMAR"),"MA CAP","MA INT"),IF($L11="PA",IF(OR(UPPER($K11)="BELEM",UPPER($K11)="BELÉM",UPPER($K11)="ANANINDEUA"),"PA CAP","PA INT"),IF($L11="PI",IF(UPPER($K11)="TERESINA","PI CAP","PI INT"),IF($L11="AM","AM INT",IF($L11="AP","AP","OUTROS")))))) -> MA CAP | N11: =IF($A11="","",IF($M11="PI CAP","GIGA+ PI",IF($M11="PI INT","GIGA+ PI",IF($M11="MA CAP","SLN MA",IF($M11="MA INT","GIGA+ MA",IF($M11="PA CAP","SLN PA",IF($M11="PA INT","SLN PA",IF($M11="AM INT","ADX",IF($M11="AP","ADX","OUTROS"))))))))) -> SLN MA | O11: =IF(F11="","",IF(INT(F11)=INT(NOW()),IF(NETWORKDAYS.INTL(F11,F11,1,FERIADOS!$A$2:$A$50)=0,0,MAX(0,(MIN(NOW(),INT(NOW())+18/24)-MAX(F11,INT(F11)+8/24)))*24),MAX(0,(INT(F11)+18/24-MAX(F11,INT(F11)+8/24)))*24*NETWORKDAYS.INTL(F11,F11,1,FERIADOS!$A$2:$A$50)+MAX(0,NETWORKDAYS.INTL(F11+1,NOW()-1,1,FERIADOS!$A$2:$A$50))*10+MAX(0,(MIN(NOW(),INT(NOW())+18/24)-(INT(NOW())+8/24)))*24*NETWORKDAYS.INTL(NOW(),NOW(),1,FERIADOS!$A$2:$A$50))) -> 10 | P11: =IF($A11="","",IF(OR(O11="",O11=0),"00h 00m",TEXT(INT(O11),"00") & "h " & TEXT(INT((O11-INT(O11))*60),"00") & "m")) -> 10h 00m | Q11: =IF($A11="","",IF(OR(O11="",O11<=4),"🔵 Até 4h",IF(O11<=8,"🟢 Entre 4h e 8h",IF(O11<=12,"🟡 Entre 8h e 12h",IF(O11<=24,"🟠 Entre 12h e 24h","🔴 Maior que 24h"))))) -> 🟡 Entre 8h e 12h | R11: =IF($A11="","",IF(OR(O11="",O11<=8),"NO PRAZO","FORA DO PRAZO")) -> FORA DO PRAZO | S11: =IF($A11="","",COUNTIF($N$2:N11,$N11)) -> 8 | T11: =IF($A11="","",IF($N11="SLN MA",1,IF($N11="GIGA+ MA",2,IF($N11="GIGA+ PI",3,IF($N11="SLN PA",4,IF($N11="ADX",5,6)))))) -> 1 | U11: =IF($A11="","",$T11*10000+$S11) -> 10008 | V11: https://atrix.mobtelecom.com.br/controle/addonmodules.php?module=helpdesk#/app/ticket/5979953
A12: 01062026-23199 | B12: SERVIS ELETRONICA DEFENSE LTDA MA | C12: CMO - Reparo | D12: REPARO | E12: SERVIS ELETRONICA DEFENSE LTDA MA GRUPO SERVIS | 218497/765 | OSCILAÇÂO | F12: 46174.879 | G12: 1 | H12: Em Espera | I12: PENDENTE AGENDAMENTO | K12: SAO LUIS | L12: MA | M12: =IF($A12="","",IF($L12="MA",IF(OR(UPPER($K12)="SAO LUIS",UPPER($K12)="SÃO LUIS",UPPER($K12)="PACO DO LUMIAR",UPPER($K12)="PAÇO DO LUMIAR",UPPER($K12)="SAO JOSE DE RIBAMAR",UPPER($K12)="SÃO JOSÉ DE RIBAMAR"),"MA CAP","MA INT"),IF($L12="PA",IF(OR(UPPER($K12)="BELEM",UPPER($K12)="BELÉM",UPPER($K12)="ANANINDEUA"),"PA CAP","PA INT"),IF($L12="PI",IF(UPPER($K12)="TERESINA","PI CAP","PI INT"),IF($L12="AM","AM INT",IF($L12="AP","AP","OUTROS")))))) -> MA CAP | N12: =IF($A12="","",IF($M12="PI CAP","GIGA+ PI",IF($M12="PI INT","GIGA+ PI",IF($M12="MA CAP","SLN MA",IF($M12="MA INT","GIGA+ MA",IF($M12="PA CAP","SLN PA",IF($M12="PA INT","SLN PA",IF($M12="AM INT","ADX",IF($M12="AP","ADX","OUTROS"))))))))) -> SLN MA | O12: =IF(F12="","",IF(INT(F12)=INT(NOW()),IF(NETWORKDAYS.INTL(F12,F12,1,FERIADOS!$A$2:$A$50)=0,0,MAX(0,(MIN(NOW(),INT(NOW())+18/24)-MAX(F12,INT(F12)+8/24)))*24),MAX(0,(INT(F12)+18/24-MAX(F12,INT(F12)+8/24)))*24*NETWORKDAYS.INTL(F12,F12,1,FERIADOS!$A$2:$A$50)+MAX(0,NETWORKDAYS.INTL(F12+1,NOW()-1,1,FERIADOS!$A$2:$A$50))*10+MAX(0,(MIN(NOW(),INT(NOW())+18/24)-(INT(NOW())+8/24)))*24*NETWORKDAYS.INTL(NOW(),NOW(),1,FERIADOS!$A$2:$A$50))) -> 10 | P12: =IF($A12="","",IF(OR(O12="",O12=0),"00h 00m",TEXT(INT(O12),"00") & "h " & TEXT(INT((O12-INT(O12))*60),"00") & "m")) -> 10h 00m | Q12: =IF($A12="","",IF(OR(O12="",O12<=4),"🔵 Até 4h",IF(O12<=8,"🟢 Entre 4h e 8h",IF(O12<=12,"🟡 Entre 8h e 12h",IF(O12<=24,"🟠 Entre 12h e 24h","🔴 Maior que 24h"))))) -> 🟡 Entre 8h e 12h | R12: =IF($A12="","",IF(OR(O12="",O12<=8),"NO PRAZO","FORA DO PRAZO")) -> FORA DO PRAZO | S12: =IF($A12="","",COUNTIF($N$2:N12,$N12)) -> 9 | T12: =IF($A12="","",IF($N12="SLN MA",1,IF($N12="GIGA+ MA",2,IF($N12="GIGA+ PI",3,IF($N12="SLN PA",4,IF($N12="ADX",5,6)))))) -> 1 | U12: =IF($A12="","",$T12*10000+$S12) -> 10009 | V12: https://atrix.mobtelecom.com.br/controle/addonmodules.php?module=helpdesk#/app/ticket/5979745
A13: 01062026-53277 | B13: TECFIBRA ISP LTDA | C13: CMO - Reparo | D13: REPARO | E13: TECFIBRA ISP LTDA TECFIBRA | PERFORMACE | ETO/IPT/229109/4 | F13: 46174.828 | G13: 1 | H13: Em atendimento | I13: AGUARDANDO DISPONIBILIDADE TECNICA | K13: ESTREITO | L13: MA | M13: =IF($A13="","",IF($L13="MA",IF(OR(UPPER($K13)="SAO LUIS",UPPER($K13)="SÃO LUIS",UPPER($K13)="PACO DO LUMIAR",UPPER($K13)="PAÇO DO LUMIAR",UPPER($K13)="SAO JOSE DE RIBAMAR",UPPER($K13)="SÃO JOSÉ DE RIBAMAR"),"MA CAP","MA INT"),IF($L13="PA",IF(OR(UPPER($K13)="BELEM",UPPER($K13)="BELÉM",UPPER($K13)="ANANINDEUA"),"PA CAP","PA INT"),IF($L13="PI",IF(UPPER($K13)="TERESINA","PI CAP","PI INT"),IF($L13="AM","AM INT",IF($L13="AP","AP","OUTROS")))))) -> MA INT | N13: =IF($A13="","",IF($M13="PI CAP","GIGA+ PI",IF($M13="PI INT","GIGA+ PI",IF($M13="MA CAP","SLN MA",IF($M13="MA INT","GIGA+ MA",IF($M13="PA CAP","SLN PA",IF($M13="PA INT","SLN PA",IF($M13="AM INT","ADX",IF($M13="AP","ADX","OUTROS"))))))))) -> GIGA+ MA | O13: =IF(F13="","",IF(INT(F13)=INT(NOW()),IF(NETWORKDAYS.INTL(F13,F13,1,FERIADOS!$A$2:$A$50)=0,0,MAX(0,(MIN(NOW(),INT(NOW())+18/24)-MAX(F13,INT(F13)+8/24)))*24),MAX(0,(INT(F13)+18/24-MAX(F13,INT(F13)+8/24)))*24*NETWORKDAYS.INTL(F13,F13,1,FERIADOS!$A$2:$A$50)+MAX(0,NETWORKDAYS.INTL(F13+1,NOW()-1,1,FERIADOS!$A$2:$A$50))*10+MAX(0,(MIN(NOW(),INT(NOW())+18/24)-(INT(NOW())+8/24)))*24*NETWORKDAYS.INTL(NOW(),NOW(),1,FERIADOS!$A$2:$A$50))) -> 10 | P13: =IF($A13="","",IF(OR(O13="",O13=0),"00h 00m",TEXT(INT(O13),"00") & "h " & TEXT(INT((O13-INT(O13))*60),"00") & "m")) -> 10h 00m | Q13: =IF($A13="","",IF(OR(O13="",O13<=4),"🔵 Até 4h",IF(O13<=8,"🟢 Entre 4h e 8h",IF(O13<=12,"🟡 Entre 8h e 12h",IF(O13<=24,"🟠 Entre 12h e 24h","🔴 Maior que 24h"))))) -> 🟡 Entre 8h e 12h | R13: =IF($A13="","",IF(OR(O13="",O13<=8),"NO PRAZO","FORA DO PRAZO")) -> FORA DO PRAZO | S13: =IF($A13="","",COUNTIF($N$2:N13,$N13)) -> 2 | T13: =IF($A13="","",IF($N13="SLN MA",1,IF($N13="GIGA+ MA",2,IF($N13="GIGA+ PI",3,IF($N13="SLN PA",4,IF($N13="ADX",5,6)))))) -> 2 | U13: =IF($A13="","",$T13*10000+$S13) -> 20002 | V13: https://atrix.mobtelecom.com.br/controle/addonmodules.php?module=helpdesk#/app/ticket/5978821
A14: 01062026-69651 | B14: MUNICIPIO DE SAO LUIS | C14: CMO - Reparo | D14: REPARO | E14: Atendimento para: CRAS CIDADE OLIMPICA - VLAN 3834 SLS-216233-00102 | F14: 46174.709 | G14: 1 | H14: Em Espera | I14: PENDENTE AGENDAMENTO | K14: SAO LUIS | L14: MA | M14: =IF($A14="","",IF($L14="MA",IF(OR(UPPER($K14)="SAO LUIS",UPPER($K14)="SÃO LUIS",UPPER($K14)="PACO DO LUMIAR",UPPER($K14)="PAÇO DO LUMIAR",UPPER($K14)="SAO JOSE DE RIBAMAR",UPPER($K14)="SÃO JOSÉ DE RIBAMAR"),"MA CAP","MA INT"),IF($L14="PA",IF(OR(UPPER($K14)="BELEM",UPPER($K14)="BELÉM",UPPER($K14)="ANANINDEUA"),"PA CAP","PA INT"),IF($L14="PI",IF(UPPER($K14)="TERESINA","PI CAP","PI INT"),IF($L14="AM","AM INT",IF($L14="AP","AP","OUTROS")))))) -> MA CAP | N14: =IF($A14="","",IF($M14="PI CAP","GIGA+ PI",IF($M14="PI INT","GIGA+ PI",IF($M14="MA CAP","SLN MA",IF($M14="MA INT","GIGA+ MA",IF($M14="PA CAP","SLN PA",IF($M14="PA INT","SLN PA",IF($M14="AM INT","ADX",IF($M14="AP","ADX","OUTROS"))))))))) -> SLN MA | O14: =IF(F14="","",IF(INT(F14)=INT(NOW()),IF(NETWORKDAYS.INTL(F14,F14,1,FERIADOS!$A$2:$A$50)=0,0,MAX(0,(MIN(NOW(),INT(NOW())+18/24)-MAX(F14,INT(F14)+8/24)))*24),MAX(0,(INT(F14)+18/24-MAX(F14,INT(F14)+8/24)))*24*NETWORKDAYS.INTL(F14,F14,1,FERIADOS!$A$2:$A$50)+MAX(0,NETWORKDAYS.INTL(F14+1,NOW()-1,1,FERIADOS!$A$2:$A$50))*10+MAX(0,(MIN(NOW(),INT(NOW())+18/24)-(INT(NOW())+8/24)))*24*NETWORKDAYS.INTL(NOW(),NOW(),1,FERIADOS!$A$2:$A$50))) -> 10.982778 | P14: =IF($A14="","",IF(OR(O14="",O14=0),"00h 00m",TEXT(INT(O14),"00") & "h " & TEXT(INT((O14-INT(O14))*60),"00") & "m")) -> 10h 58m | Q14: =IF($A14="","",IF(OR(O14="",O14<=4),"🔵 Até 4h",IF(O14<=8,"🟢 Entre 4h e 8h",IF(O14<=12,"🟡 Entre 8h e 12h",IF(O14<=24,"🟠 Entre 12h e 24h","🔴 Maior que 24h"))))) -> 🟡 Entre 8h e 12h | R14: =IF($A14="","",IF(OR(O14="",O14<=8),"NO PRAZO","FORA DO PRAZO")) -> FORA DO PRAZO | S14: =IF($A14="","",COUNTIF($N$2:N14,$N14)) -> 10 | T14: =IF($A14="","",IF($N14="SLN MA",1,IF($N14="GIGA+ MA",2,IF($N14="GIGA+ PI",3,IF($N14="SLN PA",4,IF($N14="ADX",5,6)))))) -> 1 | U14: =IF($A14="","",$T14*10000+$S14) -> 10010 | V14: https://atrix.mobtelecom.com.br/controle/addonmodules.php?module=helpdesk#/app/ticket/5978747
A15: 01062026-46968 | B15: MUNICIPIO DE SAO LUIS | C15: CMO - Reparo | D15: REPARO | E15: Atendimento para: C.T. SAO CRISTOVAO - SAO RAIMUNDO - VLAN-3838 SLS-216233-00017 | F15: 46174.702 | G15: 1 | H15: Em Espera | I15: PENDENTE AGENDAMENTO | K15: SAO LUIS | L15: MA | M15: =IF($A15="","",IF($L15="MA",IF(OR(UPPER($K15)="SAO LUIS",UPPER($K15)="SÃO LUIS",UPPER($K15)="PACO DO LUMIAR",UPPER($K15)="PAÇO DO LUMIAR",UPPER($K15)="SAO JOSE DE RIBAMAR",UPPER($K15)="SÃO JOSÉ DE RIBAMAR"),"MA CAP","MA INT"),IF($L15="PA",IF(OR(UPPER($K15)="BELEM",UPPER($K15)="BELÉM",UPPER($K15)="ANANINDEUA"),"PA CAP","PA INT"),IF($L15="PI",IF(UPPER($K15)="TERESINA","PI CAP","PI INT"),IF($L15="AM","AM INT",IF($L15="AP","AP","OUTROS")))))) -> MA CAP | N15: =IF($A15="","",IF($M15="PI CAP","GIGA+ PI",IF($M15="PI INT","GIGA+ PI",IF($M15="MA CAP","SLN MA",IF($M15="MA INT","GIGA+ MA",IF($M15="PA CAP","SLN PA",IF($M15="PA INT","SLN PA",IF($M15="AM INT","ADX",IF($M15="AP","ADX","OUTROS"))))))))) -> SLN MA | O15: =IF(F15="","",IF(INT(F15)=INT(NOW()),IF(NETWORKDAYS.INTL(F15,F15,1,FERIADOS!$A$2:$A$50)=0,0,MAX(0,(MIN(NOW(),INT(NOW())+18/24)-MAX(F15,INT(F15)+8/24)))*24),MAX(0,(INT(F15)+18/24-MAX(F15,INT(F15)+8/24)))*24*NETWORKDAYS.INTL(F15,F15,1,FERIADOS!$A$2:$A$50)+MAX(0,NETWORKDAYS.INTL(F15+1,NOW()-1,1,FERIADOS!$A$2:$A$50))*10+MAX(0,(MIN(NOW(),INT(NOW())+18/24)-(INT(NOW())+8/24)))*24*NETWORKDAYS.INTL(NOW(),NOW(),1,FERIADOS!$A$2:$A$50))) -> 11.151944 | P15: =IF($A15="","",IF(OR(O15="",O15=0),"00h 00m",TEXT(INT(O15),"00") & "h " & TEXT(INT((O15-INT(O15))*60),"00") & "m")) -> 11h 09m | Q15: =IF($A15="","",IF(OR(O15="",O15<=4),"🔵 Até 4h",IF(O15<=8,"🟢 Entre 4h e 8h",IF(O15<=12,"🟡 Entre 8h e 12h",IF(O15<=24,"🟠 Entre 12h e 24h","🔴 Maior que 24h"))))) -> 🟡 Entre 8h e 12h | R15: =IF($A15="","",IF(OR(O15="",O15<=8),"NO PRAZO","FORA DO PRAZO")) -> FORA DO PRAZO | S15: =IF($A15="","",COUNTIF($N$2:N15,$N15)) -> 11 | T15: =IF($A15="","",IF($N15="SLN MA",1,IF($N15="GIGA+ MA",2,IF($N15="GIGA+ PI",3,IF($N15="SLN PA",4,IF($N15="ADX",5,6)))))) -> 1 | U15: =IF($A15="","",$T15*10000+$S15) -> 10011 | V15: https://atrix.mobtelecom.com.br/controle/addonmodules.php?module=helpdesk#/app/ticket/5978199
A16: 01062026-33369 | B16: MUNICIPIO DE SAO LUIS | C16: CMO - Reparo | D16: REPARO | E16: Atendimento para: C.T. SAO CRISTOVAO - SAO RAIMUNDO - VLAN-3838 SLS-216233-00017 | F16: 46174.681 | G16: 1 | H16: Em Espera | I16: PENDENTE AGENDAMENTO | K16: SAO LUIS | L16: MA | M16: =IF($A16="","",IF($L16="MA",IF(OR(UPPER($K16)="SAO LUIS",UPPER($K16)="SÃO LUIS",UPPER($K16)="PACO DO LUMIAR",UPPER($K16)="PAÇO DO LUMIAR",UPPER($K16)="SAO JOSE DE RIBAMAR",UPPER($K16)="SÃO JOSÉ DE RIBAMAR"),"MA CAP","MA INT"),IF($L16="PA",IF(OR(UPPER($K16)="BELEM",UPPER($K16)="BELÉM",UPPER($K16)="ANANINDEUA"),"PA CAP","PA INT"),IF($L16="PI",IF(UPPER($K16)="TERESINA","PI CAP","PI INT"),IF($L16="AM","AM INT",IF($L16="AP","AP","OUTROS")))))) -> MA CAP | N16: =IF($A16="","",IF($M16="PI CAP","GIGA+ PI",IF($M16="PI INT","GIGA+ PI",IF($M16="MA CAP","SLN MA",IF($M16="MA INT","GIGA+ MA",IF($M16="PA CAP","SLN PA",IF($M16="PA INT","SLN PA",IF($M16="AM INT","ADX",IF($M16="AP","ADX","OUTROS"))))))))) -> SLN MA | O16: =IF(F16="","",IF(INT(F16)=INT(NOW()),IF(NETWORKDAYS.INTL(F16,F16,1,FERIADOS!$A$2:$A$50)=0,0,MAX(0,(MIN(NOW(),INT(NOW())+18/24)-MAX(F16,INT(F16)+8/24)))*24),MAX(0,(INT(F16)+18/24-MAX(F16,INT(F16)+8/24)))*24*NETWORKDAYS.INTL(F16,F16,1,FERIADOS!$A$2:$A$50)+MAX(0,NETWORKDAYS.INTL(F16+1,NOW()-1,1,FERIADOS!$A$2:$A$50))*10+MAX(0,(MIN(NOW(),INT(NOW())+18/24)-(INT(NOW())+8/24)))*24*NETWORKDAYS.INTL(NOW(),NOW(),1,FERIADOS!$A$2:$A$50))) -> 11.650278 | P16: =IF($A16="","",IF(OR(O16="",O16=0),"00h 00m",TEXT(INT(O16),"00") & "h " & TEXT(INT((O16-INT(O16))*60),"00") & "m")) -> 11h 39m | Q16: =IF($A16="","",IF(OR(O16="",O16<=4),"🔵 Até 4h",IF(O16<=8,"🟢 Entre 4h e 8h",IF(O16<=12,"🟡 Entre 8h e 12h",IF(O16<=24,"🟠 Entre 12h e 24h","🔴 Maior que 24h"))))) -> 🟡 Entre 8h e 12h | R16: =IF($A16="","",IF(OR(O16="",O16<=8),"NO PRAZO","FORA DO PRAZO")) -> FORA DO PRAZO | S16: =IF($A16="","",COUNTIF($N$2:N16,$N16)) -> 12 | T16: =IF($A16="","",IF($N16="SLN MA",1,IF($N16="GIGA+ MA",2,IF($N16="GIGA+ PI",3,IF($N16="SLN PA",4,IF($N16="ADX",5,6)))))) -> 1 | U16: =IF($A16="","",$T16*10000+$S16) -> 10012 | V16: https://atrix.mobtelecom.com.br/controle/addonmodules.php?module=helpdesk#/app/ticket/5977847
A17: 01062026-68538 | B17: FUNDO MUNICIPAL DE SAUDE DE SAO LUIS MARANHAO | C17: CMO - Reparo | D17: REPARO | E17: Atendimento para: HOSPITAL DA CRIANCA LINK 03 - LINK PRINCIPAL - SLS-IPD-218791-525 | F17: 46174.501 | G17: 1 | H17: Em Espera | I17: PENDENTE AGENDAMENTO | K17: SAO LUIS | L17: MA | M17: =IF($A17="","",IF($L17="MA",IF(OR(UPPER($K17)="SAO LUIS",UPPER($K17)="SÃO LUIS",UPPER($K17)="PACO DO LUMIAR",UPPER($K17)="PAÇO DO LUMIAR",UPPER($K17)="SAO JOSE DE RIBAMAR",UPPER($K17)="SÃO JOSÉ DE RIBAMAR"),"MA CAP","MA INT"),IF($L17="PA",IF(OR(UPPER($K17)="BELEM",UPPER($K17)="BELÉM",UPPER($K17)="ANANINDEUA"),"PA CAP","PA INT"),IF($L17="PI",IF(UPPER($K17)="TERESINA","PI CAP","PI INT"),IF($L17="AM","AM INT",IF($L17="AP","AP","OUTROS")))))) -> MA CAP | N17: =IF($A17="","",IF($M17="PI CAP","GIGA+ PI",IF($M17="PI INT","GIGA+ PI",IF($M17="MA CAP","SLN MA",IF($M17="MA INT","GIGA+ MA",IF($M17="PA CAP","SLN PA",IF($M17="PA INT","SLN PA",IF($M17="AM INT","ADX",IF($M17="AP","ADX","OUTROS"))))))))) -> SLN MA | O17: =IF(F17="","",IF(INT(F17)=INT(NOW()),IF(NETWORKDAYS.INTL(F17,F17,1,FERIADOS!$A$2:$A$50)=0,0,MAX(0,(MIN(NOW(),INT(NOW())+18/24)-MAX(F17,INT(F17)+8/24)))*24),MAX(0,(INT(F17)+18/24-MAX(F17,INT(F17)+8/24)))*24*NETWORKDAYS.INTL(F17,F17,1,FERIADOS!$A$2:$A$50)+MAX(0,NETWORKDAYS.INTL(F17+1,NOW()-1,1,FERIADOS!$A$2:$A$50))*10+MAX(0,(MIN(NOW(),INT(NOW())+18/24)-(INT(NOW())+8/24)))*24*NETWORKDAYS.INTL(NOW(),NOW(),1,FERIADOS!$A$2:$A$50))) -> 15.984722 | P17: =IF($A17="","",IF(OR(O17="",O17=0),"00h 00m",TEXT(INT(O17),"00") & "h " & TEXT(INT((O17-INT(O17))*60),"00") & "m")) -> 15h 59m | Q17: =IF($A17="","",IF(OR(O17="",O17<=4),"🔵 Até 4h",IF(O17<=8,"🟢 Entre 4h e 8h",IF(O17<=12,"🟡 Entre 8h e 12h",IF(O17<=24,"🟠 Entre 12h e 24h","🔴 Maior que 24h"))))) -> 🟠 Entre 12h e 24h | R17: =IF($A17="","",IF(OR(O17="",O17<=8),"NO PRAZO","FORA DO PRAZO")) -> FORA DO PRAZO | S17: =IF($A17="","",COUNTIF($N$2:N17,$N17)) -> 13 | T17: =IF($A17="","",IF($N17="SLN MA",1,IF($N17="GIGA+ MA",2,IF($N17="GIGA+ PI",3,IF($N17="SLN PA",4,IF($N17="ADX",5,6)))))) -> 1 | U17: =IF($A17="","",$T17*10000+$S17) -> 10013 | V17: https://atrix.mobtelecom.com.br/controle/addonmodules.php?module=helpdesk#/app/ticket/5977345
A18: 01062026-25089 | B18: RCR LOCACAO LTDA | C18: CMO - Reparo | D18: REPARO | E18: RCR LOCACAO LTDA | Indisponibilidade | SLS/IPD/226111/1 - IP 177.200.80.221 | F18: 46174.401 | G18: 1 | H18: Em Espera | I18: PENDENTE AGENDAMENTO | K18: SAO LUIS | L18: MA | M18: =IF($A18="","",IF($L18="MA",IF(OR(UPPER($K18)="SAO LUIS",UPPER($K18)="SÃO LUIS",UPPER($K18)="PACO DO LUMIAR",UPPER($K18)="PAÇO DO LUMIAR",UPPER($K18)="SAO JOSE DE RIBAMAR",UPPER($K18)="SÃO JOSÉ DE RIBAMAR"),"MA CAP","MA INT"),IF($L18="PA",IF(OR(UPPER($K18)="BELEM",UPPER($K18)="BELÉM",UPPER($K18)="ANANINDEUA"),"PA CAP","PA INT"),IF($L18="PI",IF(UPPER($K18)="TERESINA","PI CAP","PI INT"),IF($L18="AM","AM INT",IF($L18="AP","AP","OUTROS")))))) -> MA CAP | N18: =IF($A18="","",IF($M18="PI CAP","GIGA+ PI",IF($M18="PI INT","GIGA+ PI",IF($M18="MA CAP","SLN MA",IF($M18="MA INT","GIGA+ MA",IF($M18="PA CAP","SLN PA",IF($M18="PA INT","SLN PA",IF($M18="AM INT","ADX",IF($M18="AP","ADX","OUTROS"))))))))) -> SLN MA | O18: =IF(F18="","",IF(INT(F18)=INT(NOW()),IF(NETWORKDAYS.INTL(F18,F18,1,FERIADOS!$A$2:$A$50)=0,0,MAX(0,(MIN(NOW(),INT(NOW())+18/24)-MAX(F18,INT(F18)+8/24)))*24),MAX(0,(INT(F18)+18/24-MAX(F18,INT(F18)+8/24)))*24*NETWORKDAYS.INTL(F18,F18,1,FERIADOS!$A$2:$A$50)+MAX(0,NETWORKDAYS.INTL(F18+1,NOW()-1,1,FERIADOS!$A$2:$A$50))*10+MAX(0,(MIN(NOW(),INT(NOW())+18/24)-(INT(NOW())+8/24)))*24*NETWORKDAYS.INTL(NOW(),NOW(),1,FERIADOS!$A$2:$A$50))) -> 18.372222 | P18: =IF($A18="","",IF(OR(O18="",O18=0),"00h 00m",TEXT(INT(O18),"00") & "h " & TEXT(INT((O18-INT(O18))*60),"00") & "m")) -> 18h 22m | Q18: =IF($A18="","",IF(OR(O18="",O18<=4),"🔵 Até 4h",IF(O18<=8,"🟢 Entre 4h e 8h",IF(O18<=12,"🟡 Entre 8h e 12h",IF(O18<=24,"🟠 Entre 12h e 24h","🔴 Maior que 24h"))))) -> 🟠 Entre 12h e 24h | R18: =IF($A18="","",IF(OR(O18="",O18<=8),"NO PRAZO","FORA DO PRAZO")) -> FORA DO PRAZO | S18: =IF($A18="","",COUNTIF($N$2:N18,$N18)) -> 14 | T18: =IF($A18="","",IF($N18="SLN MA",1,IF($N18="GIGA+ MA",2,IF($N18="GIGA+ PI",3,IF($N18="SLN PA",4,IF($N18="ADX",5,6)))))) -> 1 | U18: =IF($A18="","",$T18*10000+$S18) -> 10014 | V18: https://atrix.mobtelecom.com.br/controle/addonmodules.php?module=helpdesk#/app/ticket/5977049
A19: 01062026-48590 | B19: COMPUSERVICE EMPREENDIMENTOS LTDA | C19: CMO - Reparo | D19: REPARO | E19: COMPUSERVICE EMPREENDIMENTOS LTDA | Indisponibilidade | FLA/IPD/117133/4 | F19: 46174.354 | G19: 1 | H19: Em atendimento | I19: AGUARDANDO DISPONIBILIDADE TECNICA | K19: ALMERIM | L19: PA | M19: =IF($A19="","",IF($L19="MA",IF(OR(UPPER($K19)="SAO LUIS",UPPER($K19)="SÃO LUIS",UPPER($K19)="PACO DO LUMIAR",UPPER($K19)="PAÇO DO LUMIAR",UPPER($K19)="SAO JOSE DE RIBAMAR",UPPER($K19)="SÃO JOSÉ DE RIBAMAR"),"MA CAP","MA INT"),IF($L19="PA",IF(OR(UPPER($K19)="BELEM",UPPER($K19)="BELÉM",UPPER($K19)="ANANINDEUA"),"PA CAP","PA INT"),IF($L19="PI",IF(UPPER($K19)="TERESINA","PI CAP","PI INT"),IF($L19="AM","AM INT",IF($L19="AP","AP","OUTROS")))))) -> PA INT | N19: =IF($A19="","",IF($M19="PI CAP","GIGA+ PI",IF($M19="PI INT","GIGA+ PI",IF($M19="MA CAP","SLN MA",IF($M19="MA INT","GIGA+ MA",IF($M19="PA CAP","SLN PA",IF($M19="PA INT","SLN PA",IF($M19="AM INT","ADX",IF($M19="AP","ADX","OUTROS"))))))))) -> SLN PA | O19: =IF(F19="","",IF(INT(F19)=INT(NOW()),IF(NETWORKDAYS.INTL(F19,F19,1,FERIADOS!$A$2:$A$50)=0,0,MAX(0,(MIN(NOW(),INT(NOW())+18/24)-MAX(F19,INT(F19)+8/24)))*24),MAX(0,(INT(F19)+18/24-MAX(F19,INT(F19)+8/24)))*24*NETWORKDAYS.INTL(F19,F19,1,FERIADOS!$A$2:$A$50)+MAX(0,NETWORKDAYS.INTL(F19+1,NOW()-1,1,FERIADOS!$A$2:$A$50))*10+MAX(0,(MIN(NOW(),INT(NOW())+18/24)-(INT(NOW())+8/24)))*24*NETWORKDAYS.INTL(NOW(),NOW(),1,FERIADOS!$A$2:$A$50))) -> 19.507222 | P19: =IF($A19="","",IF(OR(O19="",O19=0),"00h 00m",TEXT(INT(O19),"00") & "h " & TEXT(INT((O19-INT(O19))*60),"00") & "m")) -> 19h 30m | Q19: =IF($A19="","",IF(OR(O19="",O19<=4),"🔵 Até 4h",IF(O19<=8,"🟢 Entre 4h e 8h",IF(O19<=12,"🟡 Entre 8h e 12h",IF(O19<=24,"🟠 Entre 12h e 24h","🔴 Maior que 24h"))))) -> 🟠 Entre 12h e 24h | R19: =IF($A19="","",IF(OR(O19="",O19<=8),"NO PRAZO","FORA DO PRAZO")) -> FORA DO PRAZO | S19: =IF($A19="","",COUNTIF($N$2:N19,$N19)) -> 1 | T19: =IF($A19="","",IF($N19="SLN MA",1,IF($N19="GIGA+ MA",2,IF($N19="GIGA+ PI",3,IF($N19="SLN PA",4,IF($N19="ADX",5,6)))))) -> 4 | U19: =IF($A19="","",$T19*10000+$S19) -> 40001 | V19: https://atrix.mobtelecom.com.br/controle/addonmodules.php?module=helpdesk#/app/ticket/5980941
M20: =IF($A20="","",IF($L20="MA",IF(OR(UPPER($K20)="SAO LUIS",UPPER($K20)="SÃO LUIS",UPPER($K20)="PACO DO LUMIAR",UPPER($K20)="PAÇO DO LUMIAR",UPPER($K20)="SAO JOSE DE RIBAMAR",UPPER($K20)="SÃO JOSÉ DE RIBAMAR"),"MA CAP","MA INT"),IF($L20="PA",IF(OR(UPPER($K20)="BELEM",UPPER($K20)="BELÉM",UPPER($K20)="ANANINDEUA"),"PA CAP","PA INT"),IF($L20="PI",IF(UPPER($K20)="TERESINA","PI CAP","PI INT"),IF($L20="AM","AM INT",IF($L20="AP","AP","OUTROS")))))) | N20: =IF($A20="","",IF($M20="PI CAP","GIGA+ PI",IF($M20="PI INT","GIGA+ PI",IF($M20="MA CAP","SLN MA",IF($M20="MA INT","GIGA+ MA",IF($M20="PA CAP","SLN PA",IF($M20="PA INT","SLN PA",IF($M20="AM INT","ADX",IF($M20="AP","ADX","OUTROS"))))))))) | O20: =IF(F20="","",IF(INT(F20)=INT(NOW()),IF(NETWORKDAYS.INTL(F20,F20,1,FERIADOS!$A$2:$A$50)=0,0,MAX(0,(MIN(NOW(),INT(NOW())+18/24)-MAX(F20,INT(F20)+8/24)))*24),MAX(0,(INT(F20)+18/24-MAX(F20,INT(F20)+8/24)))*24*NETWORKDAYS.INTL(F20,F20,1,FERIADOS!$A$2:$A$50)+MAX(0,NETWORKDAYS.INTL(F20+1,NOW()-1,1,FERIADOS!$A$2:$A$50))*10+MAX(0,(MIN(NOW(),INT(NOW())+18/24)-(INT(NOW())+8/24)))*24*NETWORKDAYS.INTL(NOW(),NOW(),1,FERIADOS!$A$2:$A$50))) | P20: =IF($A20="","",IF(OR(O20="",O20=0),"00h 00m",TEXT(INT(O20),"00") & "h " & TEXT(INT((O20-INT(O20))*60),"00") & "m")) | Q20: =IF($A20="","",IF(OR(O20="",O20<=4),"🔵 Até 4h",IF(O20<=8,"🟢 Entre 4h e 8h",IF(O20<=12,"🟡 Entre 8h e 12h",IF(O20<=24,"🟠 Entre 12h e 24h","🔴 Maior que 24h"))))) | R20: =IF($A20="","",IF(OR(O20="",O20<=8),"NO PRAZO","FORA DO PRAZO")) | S20: =IF($A20="","",COUNTIF($N$2:N20,$N20)) | T20: =IF($A20="","",IF($N20="SLN MA",1,IF($N20="GIGA+ MA",2,IF($N20="GIGA+ PI",3,IF($N20="SLN PA",4,IF($N20="ADX",5,6)))))) | U20: =IF($A20="","",$T20*10000+$S20) | V20: https://atrix.mobtelecom.com.br/controle/addonmodules.php?module=helpdesk#/app/ticket/5980901
M21: =IF($A21="","",IF($L21="MA",IF(OR(UPPER($K21)="SAO LUIS",UPPER($K21)="SÃO LUIS",UPPER($K21)="PACO DO LUMIAR",UPPER($K21)="PAÇO DO LUMIAR",UPPER($K21)="SAO JOSE DE RIBAMAR",UPPER($K21)="SÃO JOSÉ DE RIBAMAR"),"MA CAP","MA INT"),IF($L21="PA",IF(OR(UPPER($K21)="BELEM",UPPER($K21)="BELÉM",UPPER($K21)="ANANINDEUA"),"PA CAP","PA INT"),IF($L21="PI",IF(UPPER($K21)="TERESINA","PI CAP","PI INT"),IF($L21="AM","AM INT",IF($L21="AP","AP","OUTROS")))))) | N21: =IF($A21="","",IF($M21="PI CAP","GIGA+ PI",IF($M21="PI INT","GIGA+ PI",IF($M21="MA CAP","SLN MA",IF($M21="MA INT","GIGA+ MA",IF($M21="PA CAP","SLN PA",IF($M21="PA INT","SLN PA",IF($M21="AM INT","ADX",IF($M21="AP","ADX","OUTROS"))))))))) | O21: =IF(F21="","",IF(INT(F21)=INT(NOW()),IF(NETWORKDAYS.INTL(F21,F21,1,FERIADOS!$A$2:$A$50)=0,0,MAX(0,(MIN(NOW(),INT(NOW())+18/24)-MAX(F21,INT(F21)+8/24)))*24),MAX(0,(INT(F21)+18/24-MAX(F21,INT(F21)+8/24)))*24*NETWORKDAYS.INTL(F21,F21,1,FERIADOS!$A$2:$A$50)+MAX(0,NETWORKDAYS.INTL(F21+1,NOW()-1,1,FERIADOS!$A$2:$A$50))*10+MAX(0,(MIN(NOW(),INT(NOW())+18/24)-(INT(NOW())+8/24)))*24*NETWORKDAYS.INTL(NOW(),NOW(),1,FERIADOS!$A$2:$A$50))) | P21: =IF($A21="","",IF(OR(O21="",O21=0),"00h 00m",TEXT(INT(O21),"00") & "h " & TEXT(INT((O21-INT(O21))*60),"00") & "m")) | Q21: =IF($A21="","",IF(OR(O21="",O21<=4),"🔵 Até 4h",IF(O21<=8,"🟢 Entre 4h e 8h",IF(O21<=12,"🟡 Entre 8h e 12h",IF(O21<=24,"🟠 Entre 12h e 24h","🔴 Maior que 24h"))))) | R21: =IF($A21="","",IF(OR(O21="",O21<=8),"NO PRAZO","FORA DO PRAZO")) | S21: =IF($A21="","",COUNTIF($N$2:N21,$N21)) | T21: =IF($A21="","",IF($N21="SLN MA",1,IF($N21="GIGA+ MA",2,IF($N21="GIGA+ PI",3,IF($N21="SLN PA",4,IF($N21="ADX",5,6)))))) | U21: =IF($A21="","",$T21*10000+$S21) | V21: https://atrix.mobtelecom.com.br/controle/addonmodules.php?module=helpdesk#/app/ticket/5980883
M22: =IF($A22="","",IF($L22="MA",IF(OR(UPPER($K22)="SAO LUIS",UPPER($K22)="SÃO LUIS",UPPER($K22)="PACO DO LUMIAR",UPPER($K22)="PAÇO DO LUMIAR",UPPER($K22)="SAO JOSE DE RIBAMAR",UPPER($K22)="SÃO JOSÉ DE RIBAMAR"),"MA CAP","MA INT"),IF($L22="PA",IF(OR(UPPER($K22)="BELEM",UPPER($K22)="BELÉM",UPPER($K22)="ANANINDEUA"),"PA CAP","PA INT"),IF($L22="PI",IF(UPPER($K22)="TERESINA","PI CAP","PI INT"),IF($L22="AM","AM INT",IF($L22="AP","AP","OUTROS")))))) | N22: =IF($A22="","",IF($M22="PI CAP","GIGA+ PI",IF($M22="PI INT","GIGA+ PI",IF($M22="MA CAP","SLN MA",IF($M22="MA INT","GIGA+ MA",IF($M22="PA CAP","SLN PA",IF($M22="PA INT","SLN PA",IF($M22="AM INT","ADX",IF($M22="AP","ADX","OUTROS"))))))))) | O22: =IF(F22="","",IF(INT(F22)=INT(NOW()),IF(NETWORKDAYS.INTL(F22,F22,1,FERIADOS!$A$2:$A$50)=0,0,MAX(0,(MIN(NOW(),INT(NOW())+18/24)-MAX(F22,INT(F22)+8/24)))*24),MAX(0,(INT(F22)+18/24-MAX(F22,INT(F22)+8/24)))*24*NETWORKDAYS.INTL(F22,F22,1,FERIADOS!$A$2:$A$50)+MAX(0,NETWORKDAYS.INTL(F22+1,NOW()-1,1,FERIADOS!$A$2:$A$50))*10+MAX(0,(MIN(NOW(),INT(NOW())+18/24)-(INT(NOW())+8/24)))*24*NETWORKDAYS.INTL(NOW(),NOW(),1,FERIADOS!$A$2:$A$50))) | P22: =IF($A22="","",IF(OR(O22="",O22=0),"00h 00m",TEXT(INT(O22),"00") & "h " & TEXT(INT((O22-INT(O22))*60),"00") & "m")) | Q22: =IF($A22="","",IF(OR(O22="",O22<=4),"🔵 Até 4h",IF(O22<=8,"🟢 Entre 4h e 8h",IF(O22<=12,"🟡 Entre 8h e 12h",IF(O22<=24,"🟠 Entre 12h e 24h","🔴 Maior que 24h"))))) | R22: =IF($A22="","",IF(OR(O22="",O22<=8),"NO PRAZO","FORA DO PRAZO")) | S22: =IF($A22="","",COUNTIF($N$2:N22,$N22)) | T22: =IF($A22="","",IF($N22="SLN MA",1,IF($N22="GIGA+ MA",2,IF($N22="GIGA+ PI",3,IF($N22="SLN PA",4,IF($N22="ADX",5,6)))))) | U22: =IF($A22="","",$T22*10000+$S22) | V22: https://atrix.mobtelecom.com.br/controle/addonmodules.php?module=helpdesk#/app/ticket/5980545
M23: =IF($A23="","",IF($L23="MA",IF(OR(UPPER($K23)="SAO LUIS",UPPER($K23)="SÃO LUIS",UPPER($K23)="PACO DO LUMIAR",UPPER($K23)="PAÇO DO LUMIAR",UPPER($K23)="SAO JOSE DE RIBAMAR",UPPER($K23)="SÃO JOSÉ DE RIBAMAR"),"MA CAP","MA INT"),IF($L23="PA",IF(OR(UPPER($K23)="BELEM",UPPER($K23)="BELÉM",UPPER($K23)="ANANINDEUA"),"PA CAP","PA INT"),IF($L23="PI",IF(UPPER($K23)="TERESINA","PI CAP","PI INT"),IF($L23="AM","AM INT",IF($L23="AP","AP","OUTROS")))))) | N23: =IF($A23="","",IF($M23="PI CAP","GIGA+ PI",IF($M23="PI INT","GIGA+ PI",IF($M23="MA CAP","SLN MA",IF($M23="MA INT","GIGA+ MA",IF($M23="PA CAP","SLN PA",IF($M23="PA INT","SLN PA",IF($M23="AM INT","ADX",IF($M23="AP","ADX","OUTROS"))))))))) | O23: =IF(F23="","",IF(INT(F23)=INT(NOW()),IF(NETWORKDAYS.INTL(F23,F23,1,FERIADOS!$A$2:$A$50)=0,0,MAX(0,(MIN(NOW(),INT(NOW())+18/24)-MAX(F23,INT(F23)+8/24)))*24),MAX(0,(INT(F23)+18/24-MAX(F23,INT(F23)+8/24)))*24*NETWORKDAYS.INTL(F23,F23,1,FERIADOS!$A$2:$A$50)+MAX(0,NETWORKDAYS.INTL(F23+1,NOW()-1,1,FERIADOS!$A$2:$A$50))*10+MAX(0,(MIN(NOW(),INT(NOW())+18/24)-(INT(NOW())+8/24)))*24*NETWORKDAYS.INTL(NOW(),NOW(),1,FERIADOS!$A$2:$A$50))) | P23: =IF($A23="","",IF(OR(O23="",O23=0),"00h 00m",TEXT(INT(O23),"00") & "h " & TEXT(INT((O23-INT(O23))*60),"00") & "m")) | Q23: =IF($A23="","",IF(OR(O23="",O23<=4),"🔵 Até 4h",IF(O23<=8,"🟢 Entre 4h e 8h",IF(O23<=12,"🟡 Entre 8h e 12h",IF(O23<=24,"🟠 Entre 12h e 24h","🔴 Maior que 24h"))))) | R23: =IF($A23="","",IF(OR(O23="",O23<=8),"NO PRAZO","FORA DO PRAZO")) | S23: =IF($A23="","",COUNTIF($N$2:N23,$N23)) | T23: =IF($A23="","",IF($N23="SLN MA",1,IF($N23="GIGA+ MA",2,IF($N23="GIGA+ PI",3,IF($N23="SLN PA",4,IF($N23="ADX",5,6)))))) | U23: =IF($A23="","",$T23*10000+$S23) | V23: https://atrix.mobtelecom.com.br/controle/addonmodules.php?module=helpdesk#/app/ticket/5980479
M24: =IF($A24="","",IF($L24="MA",IF(OR(UPPER($K24)="SAO LUIS",UPPER($K24)="SÃO LUIS",UPPER($K24)="PACO DO LUMIAR",UPPER($K24)="PAÇO DO LUMIAR",UPPER($K24)="SAO JOSE DE RIBAMAR",UPPER($K24)="SÃO JOSÉ DE RIBAMAR"),"MA CAP","MA INT"),IF($L24="PA",IF(OR(UPPER($K24)="BELEM",UPPER($K24)="BELÉM",UPPER($K24)="ANANINDEUA"),"PA CAP","PA INT"),IF($L24="PI",IF(UPPER($K24)="TERESINA","PI CAP","PI INT"),IF($L24="AM","AM INT",IF($L24="AP","AP","OUTROS")))))) | N24: =IF($A24="","",IF($M24="PI CAP","GIGA+ PI",IF($M24="PI INT","GIGA+ PI",IF($M24="MA CAP","SLN MA",IF($M24="MA INT","GIGA+ MA",IF($M24="PA CAP","SLN PA",IF($M24="PA INT","SLN PA",IF($M24="AM INT","ADX",IF($M24="AP","ADX","OUTROS"))))))))) | O24: =IF(F24="","",IF(INT(F24)=INT(NOW()),IF(NETWORKDAYS.INTL(F24,F24,1,FERIADOS!$A$2:$A$50)=0,0,MAX(0,(MIN(NOW(),INT(NOW())+18/24)-MAX(F24,INT(F24)+8/24)))*24),MAX(0,(INT(F24)+18/24-MAX(F24,INT(F24)+8/24)))*24*NETWORKDAYS.INTL(F24,F24,1,FERIADOS!$A$2:$A$50)+MAX(0,NETWORKDAYS.INTL(F24+1,NOW()-1,1,FERIADOS!$A$2:$A$50))*10+MAX(0,(MIN(NOW(),INT(NOW())+18/24)-(INT(NOW())+8/24)))*24*NETWORKDAYS.INTL(NOW(),NOW(),1,FERIADOS!$A$2:$A$50))) | P24: =IF($A24="","",IF(OR(O24="",O24=0),"00h 00m",TEXT(INT(O24),"00") & "h " & TEXT(INT((O24-INT(O24))*60),"00") & "m")) | Q24: =IF($A24="","",IF(OR(O24="",O24<=4),"🔵 Até 4h",IF(O24<=8,"🟢 Entre 4h e 8h",IF(O24<=12,"🟡 Entre 8h e 12h",IF(O24<=24,"🟠 Entre 12h e 24h","🔴 Maior que 24h"))))) | R24: =IF($A24="","",IF(OR(O24="",O24<=8),"NO PRAZO","FORA DO PRAZO")) | S24: =IF($A24="","",COUNTIF($N$2:N24,$N24)) | T24: =IF($A24="","",IF($N24="SLN MA",1,IF($N24="GIGA+ MA",2,IF($N24="GIGA+ PI",3,IF($N24="SLN PA",4,IF($N24="ADX",5,6)))))) | U24: =IF($A24="","",$T24*10000+$S24) | V24: https://atrix.mobtelecom.com.br/controle/addonmodules.php?module=helpdesk#/app/ticket/5980397
M25: =IF($A25="","",IF($L25="MA",IF(OR(UPPER($K25)="SAO LUIS",UPPER($K25)="SÃO LUIS",UPPER($K25)="PACO DO LUMIAR",UPPER($K25)="PAÇO DO LUMIAR",UPPER($K25)="SAO JOSE DE RIBAMAR",UPPER($K25)="SÃO JOSÉ DE RIBAMAR"),"MA CAP","MA INT"),IF($L25="PA",IF(OR(UPPER($K25)="BELEM",UPPER($K25)="BELÉM",UPPER($K25)="ANANINDEUA"),"PA CAP","PA INT"),IF($L25="PI",IF(UPPER($K25)="TERESINA","PI CAP","PI INT"),IF($L25="AM","AM INT",IF($L25="AP","AP","OUTROS")))))) | N25: =IF($A25="","",IF($M25="PI CAP","GIGA+ PI",IF($M25="PI INT","GIGA+ PI",IF($M25="MA CAP","SLN MA",IF($M25="MA INT","GIGA+ MA",IF($M25="PA CAP","SLN PA",IF($M25="PA INT","SLN PA",IF($M25="AM INT","ADX",IF($M25="AP","ADX","OUTROS"))))))))) | O25: =IF(F25="","",IF(INT(F25)=INT(NOW()),IF(NETWORKDAYS.INTL(F25,F25,1,FERIADOS!$A$2:$A$50)=0,0,MAX(0,(MIN(NOW(),INT(NOW())+18/24)-MAX(F25,INT(F25)+8/24)))*24),MAX(0,(INT(F25)+18/24-MAX(F25,INT(F25)+8/24)))*24*NETWORKDAYS.INTL(F25,F25,1,FERIADOS!$A$2:$A$50)+MAX(0,NETWORKDAYS.INTL(F25+1,NOW()-1,1,FERIADOS!$A$2:$A$50))*10+MAX(0,(MIN(NOW(),INT(NOW())+18/24)-(INT(NOW())+8/24)))*24*NETWORKDAYS.INTL(NOW(),NOW(),1,FERIADOS!$A$2:$A$50))) | P25: =IF($A25="","",IF(OR(O25="",O25=0),"00h 00m",TEXT(INT(O25),"00") & "h " & TEXT(INT((O25-INT(O25))*60),"00") & "m")) | Q25: =IF($A25="","",IF(OR(O25="",O25<=4),"🔵 Até 4h",IF(O25<=8,"🟢 Entre 4h e 8h",IF(O25<=12,"🟡 Entre 8h e 12h",IF(O25<=24,"🟠 Entre 12h e 24h","🔴 Maior que 24h"))))) | R25: =IF($A25="","",IF(OR(O25="",O25<=8),"NO PRAZO","FORA DO PRAZO")) | S25: =IF($A25="","",COUNTIF($N$2:N25,$N25)) | T25: =IF($A25="","",IF($N25="SLN MA",1,IF($N25="GIGA+ MA",2,IF($N25="GIGA+ PI",3,IF($N25="SLN PA",4,IF($N25="ADX",5,6)))))) | U25: =IF($A25="","",$T25*10000+$S25) | V25: https://atrix.mobtelecom.com.br/controle/addonmodules.php?module=helpdesk#/app/ticket/5980393
M26: =IF($A26="","",IF($L26="MA",IF(OR(UPPER($K26)="SAO LUIS",UPPER($K26)="SÃO LUIS",UPPER($K26)="PACO DO LUMIAR",UPPER($K26)="PAÇO DO LUMIAR",UPPER($K26)="SAO JOSE DE RIBAMAR",UPPER($K26)="SÃO JOSÉ DE RIBAMAR"),"MA CAP","MA INT"),IF($L26="PA",IF(OR(UPPER($K26)="BELEM",UPPER($K26)="BELÉM",UPPER($K26)="ANANINDEUA"),"PA CAP","PA INT"),IF($L26="PI",IF(UPPER($K26)="TERESINA","PI CAP","PI INT"),IF($L26="AM","AM INT",IF($L26="AP","AP","OUTROS")))))) | N26: =IF($A26="","",IF($M26="PI CAP","GIGA+ PI",IF($M26="PI INT","GIGA+ PI",IF($M26="MA CAP","SLN MA",IF($M26="MA INT","GIGA+ MA",IF($M26="PA CAP","SLN PA",IF($M26="PA INT","SLN PA",IF($M26="AM INT","ADX",IF($M26="AP","ADX","OUTROS"))))))))) | O26: =IF(F26="","",IF(INT(F26)=INT(NOW()),IF(NETWORKDAYS.INTL(F26,F26,1,FERIADOS!$A$2:$A$50)=0,0,MAX(0,(MIN(NOW(),INT(NOW())+18/24)-MAX(F26,INT(F26)+8/24)))*24),MAX(0,(INT(F26)+18/24-MAX(F26,INT(F26)+8/24)))*24*NETWORKDAYS.INTL(F26,F26,1,FERIADOS!$A$2:$A$50)+MAX(0,NETWORKDAYS.INTL(F26+1,NOW()-1,1,FERIADOS!$A$2:$A$50))*10+MAX(0,(MIN(NOW(),INT(NOW())+18/24)-(INT(NOW())+8/24)))*24*NETWORKDAYS.INTL(NOW(),NOW(),1,FERIADOS!$A$2:$A$50))) | P26: =IF($A26="","",IF(OR(O26="",O26=0),"00h 00m",TEXT(INT(O26),"00") & "h " & TEXT(INT((O26-INT(O26))*60),"00") & "m")) | Q26: =IF($A26="","",IF(OR(O26="",O26<=4),"🔵 Até 4h",IF(O26<=8,"🟢 Entre 4h e 8h",IF(O26<=12,"🟡 Entre 8h e 12h",IF(O26<=24,"🟠 Entre 12h e 24h","🔴 Maior que 24h"))))) | R26: =IF($A26="","",IF(OR(O26="",O26<=8),"NO PRAZO","FORA DO PRAZO")) | S26: =IF($A26="","",COUNTIF($N$2:N26,$N26)) | T26: =IF($A26="","",IF($N26="SLN MA",1,IF($N26="GIGA+ MA",2,IF($N26="GIGA+ PI",3,IF($N26="SLN PA",4,IF($N26="ADX",5,6)))))) | U26: =IF($A26="","",$T26*10000+$S26) | V26: https://atrix.mobtelecom.com.br/controle/addonmodules.php?module=helpdesk#/app/ticket/5980243
M27: =IF($A27="","",IF($L27="MA",IF(OR(UPPER($K27)="SAO LUIS",UPPER($K27)="SÃO LUIS",UPPER($K27)="PACO DO LUMIAR",UPPER($K27)="PAÇO DO LUMIAR",UPPER($K27)="SAO JOSE DE RIBAMAR",UPPER($K27)="SÃO JOSÉ DE RIBAMAR"),"MA CAP","MA INT"),IF($L27="PA",IF(OR(UPPER($K27)="BELEM",UPPER($K27)="BELÉM",UPPER($K27)="ANANINDEUA"),"PA CAP","PA INT"),IF($L27="PI",IF(UPPER($K27)="TERESINA","PI CAP","PI INT"),IF($L27="AM","AM INT",IF($L27="AP","AP","OUTROS")))))) | N27: =IF($A27="","",IF($M27="PI CAP","GIGA+ PI",IF($M27="PI INT","GIGA+ PI",IF($M27="MA CAP","SLN MA",IF($M27="MA INT","GIGA+ MA",IF($M27="PA CAP","SLN PA",IF($M27="PA INT","SLN PA",IF($M27="AM INT","ADX",IF($M27="AP","ADX","OUTROS"))))))))) | O27: =IF(F27="","",IF(INT(F27)=INT(NOW()),IF(NETWORKDAYS.INTL(F27,F27,1,FERIADOS!$A$2:$A$50)=0,0,MAX(0,(MIN(NOW(),INT(NOW())+18/24)-MAX(F27,INT(F27)+8/24)))*24),MAX(0,(INT(F27)+18/24-MAX(F27,INT(F27)+8/24)))*24*NETWORKDAYS.INTL(F27,F27,1,FERIADOS!$A$2:$A$50)+MAX(0,NETWORKDAYS.INTL(F27+1,NOW()-1,1,FERIADOS!$A$2:$A$50))*10+MAX(0,(MIN(NOW(),INT(NOW())+18/24)-(INT(NOW())+8/24)))*24*NETWORKDAYS.INTL(NOW(),NOW(),1,FERIADOS!$A$2:$A$50))) | P27: =IF($A27="","",IF(OR(O27="",O27=0),"00h 00m",TEXT(INT(O27),"00") & "h " & TEXT(INT((O27-INT(O27))*60),"00") & "m")) | Q27: =IF($A27="","",IF(OR(O27="",O27<=4),"🔵 Até 4h",IF(O27<=8,"🟢 Entre 4h e 8h",IF(O27<=12,"🟡 Entre 8h e 12h",IF(O27<=24,"🟠 Entre 12h e 24h","🔴 Maior que 24h"))))) | R27: =IF($A27="","",IF(OR(O27="",O27<=8),"NO PRAZO","FORA DO PRAZO")) | S27: =IF($A27="","",COUNTIF($N$2:N27,$N27)) | T27: =IF($A27="","",IF($N27="SLN MA",1,IF($N27="GIGA+ MA",2,IF($N27="GIGA+ PI",3,IF($N27="SLN PA",4,IF($N27="ADX",5,6)))))) | U27: =IF($A27="","",$T27*10000+$S27) | V27: https://atrix.mobtelecom.com.br/controle/addonmodules.php?module=helpdesk#/app/ticket/5980133
M28: =IF($A28="","",IF($L28="MA",IF(OR(UPPER($K28)="SAO LUIS",UPPER($K28)="SÃO LUIS",UPPER($K28)="PACO DO LUMIAR",UPPER($K28)="PAÇO DO LUMIAR",UPPER($K28)="SAO JOSE DE RIBAMAR",UPPER($K28)="SÃO JOSÉ DE RIBAMAR"),"MA CAP","MA INT"),IF($L28="PA",IF(OR(UPPER($K28)="BELEM",UPPER($K28)="BELÉM",UPPER($K28)="ANANINDEUA"),"PA CAP","PA INT"),IF($L28="PI",IF(UPPER($K28)="TERESINA","PI CAP","PI INT"),IF($L28="AM","AM INT",IF($L28="AP","AP","OUTROS")))))) | N28: =IF($A28="","",IF($M28="PI CAP","GIGA+ PI",IF($M28="PI INT","GIGA+ PI",IF($M28="MA CAP","SLN MA",IF($M28="MA INT","GIGA+ MA",IF($M28="PA CAP","SLN PA",IF($M28="PA INT","SLN PA",IF($M28="AM INT","ADX",IF($M28="AP","ADX","OUTROS"))))))))) | O28: =IF(F28="","",IF(INT(F28)=INT(NOW()),IF(NETWORKDAYS.INTL(F28,F28,1,FERIADOS!$A$2:$A$50)=0,0,MAX(0,(MIN(NOW(),INT(NOW())+18/24)-MAX(F28,INT(F28)+8/24)))*24),MAX(0,(INT(F28)+18/24-MAX(F28,INT(F28)+8/24)))*24*NETWORKDAYS.INTL(F28,F28,1,FERIADOS!$A$2:$A$50)+MAX(0,NETWORKDAYS.INTL(F28+1,NOW()-1,1,FERIADOS!$A$2:$A$50))*10+MAX(0,(MIN(NOW(),INT(NOW())+18/24)-(INT(NOW())+8/24)))*24*NETWORKDAYS.INTL(NOW(),NOW(),1,FERIADOS!$A$2:$A$50))) | P28: =IF($A28="","",IF(OR(O28="",O28=0),"00h 00m",TEXT(INT(O28),"00") & "h " & TEXT(INT((O28-INT(O28))*60),"00") & "m")) | Q28: =IF($A28="","",IF(OR(O28="",O28<=4),"🔵 Até 4h",IF(O28<=8,"🟢 Entre 4h e 8h",IF(O28<=12,"🟡 Entre 8h e 12h",IF(O28<=24,"🟠 Entre 12h e 24h","🔴 Maior que 24h"))))) | R28: =IF($A28="","",IF(OR(O28="",O28<=8),"NO PRAZO","FORA DO PRAZO")) | S28: =IF($A28="","",COUNTIF($N$2:N28,$N28)) | T28: =IF($A28="","",IF($N28="SLN MA",1,IF($N28="GIGA+ MA",2,IF($N28="GIGA+ PI",3,IF($N28="SLN PA",4,IF($N28="ADX",5,6)))))) | U28: =IF($A28="","",$T28*10000+$S28) | V28: https://atrix.mobtelecom.com.br/controle/addonmodules.php?module=helpdesk#/app/ticket/5977029
M29: =IF($A29="","",IF($L29="MA",IF(OR(UPPER($K29)="SAO LUIS",UPPER($K29)="SÃO LUIS",UPPER($K29)="PACO DO LUMIAR",UPPER($K29)="PAÇO DO LUMIAR",UPPER($K29)="SAO JOSE DE RIBAMAR",UPPER($K29)="SÃO JOSÉ DE RIBAMAR"),"MA CAP","MA INT"),IF($L29="PA",IF(OR(UPPER($K29)="BELEM",UPPER($K29)="BELÉM",UPPER($K29)="ANANINDEUA"),"PA CAP","PA INT"),IF($L29="PI",IF(UPPER($K29)="TERESINA","PI CAP","PI INT"),IF($L29="AM","AM INT",IF($L29="AP","AP","OUTROS")))))) | N29: =IF($A29="","",IF($M29="PI CAP","GIGA+ PI",IF($M29="PI INT","GIGA+ PI",IF($M29="MA CAP","SLN MA",IF($M29="MA INT","GIGA+ MA",IF($M29="PA CAP","SLN PA",IF($M29="PA INT","SLN PA",IF($M29="AM INT","ADX",IF($M29="AP","ADX","OUTROS"))))))))) | O29: =IF(F29="","",IF(INT(F29)=INT(NOW()),IF(NETWORKDAYS.INTL(F29,F29,1,FERIADOS!$A$2:$A$50)=0,0,MAX(0,(MIN(NOW(),INT(NOW())+18/24)-MAX(F29,INT(F29)+8/24)))*24),MAX(0,(INT(F29)+18/24-MAX(F29,INT(F29)+8/24)))*24*NETWORKDAYS.INTL(F29,F29,1,FERIADOS!$A$2:$A$50)+MAX(0,NETWORKDAYS.INTL(F29+1,NOW()-1,1,FERIADOS!$A$2:$A$50))*10+MAX(0,(MIN(NOW(),INT(NOW())+18/24)-(INT(NOW())+8/24)))*24*NETWORKDAYS.INTL(NOW(),NOW(),1,FERIADOS!$A$2:$A$50))) | P29: =IF($A29="","",IF(OR(O29="",O29=0),"00h 00m",TEXT(INT(O29),"00") & "h " & TEXT(INT((O29-INT(O29))*60),"00") & "m")) | Q29: =IF($A29="","",IF(OR(O29="",O29<=4),"🔵 Até 4h",IF(O29<=8,"🟢 Entre 4h e 8h",IF(O29<=12,"🟡 Entre 8h e 12h",IF(O29<=24,"🟠 Entre 12h e 24h","🔴 Maior que 24h"))))) | R29: =IF($A29="","",IF(OR(O29="",O29<=8),"NO PRAZO","FORA DO PRAZO")) | S29: =IF($A29="","",COUNTIF($N$2:N29,$N29)) | T29: =IF($A29="","",IF($N29="SLN MA",1,IF($N29="GIGA+ MA",2,IF($N29="GIGA+ PI",3,IF($N29="SLN PA",4,IF($N29="ADX",5,6)))))) | U29: =IF($A29="","",$T29*10000+$S29) | V29: https://atrix.mobtelecom.com.br/controle/addonmodules.php?module=helpdesk#/app/ticket/5976823
M30: =IF($A30="","",IF($L30="MA",IF(OR(UPPER($K30)="SAO LUIS",UPPER($K30)="SÃO LUIS",UPPER($K30)="PACO DO LUMIAR",UPPER($K30)="PAÇO DO LUMIAR",UPPER($K30)="SAO JOSE DE RIBAMAR",UPPER($K30)="SÃO JOSÉ DE RIBAMAR"),"MA CAP","MA INT"),IF($L30="PA",IF(OR(UPPER($K30)="BELEM",UPPER($K30)="BELÉM",UPPER($K30)="ANANINDEUA"),"PA CAP","PA INT"),IF($L30="PI",IF(UPPER($K30)="TERESINA","PI CAP","PI INT"),IF($L30="AM","AM INT",IF($L30="AP","AP","OUTROS")))))) | N30: =IF($A30="","",IF($M30="PI CAP","GIGA+ PI",IF($M30="PI INT","GIGA+ PI",IF($M30="MA CAP","SLN MA",IF($M30="MA INT","GIGA+ MA",IF($M30="PA CAP","SLN PA",IF($M30="PA INT","SLN PA",IF($M30="AM INT","ADX",IF($M30="AP","ADX","OUTROS"))))))))) | O30: =IF(F30="","",IF(INT(F30)=INT(NOW()),IF(NETWORKDAYS.INTL(F30,F30,1,FERIADOS!$A$2:$A$50)=0,0,MAX(0,(MIN(NOW(),INT(NOW())+18/24)-MAX(F30,INT(F30)+8/24)))*24),MAX(0,(INT(F30)+18/24-MAX(F30,INT(F30)+8/24)))*24*NETWORKDAYS.INTL(F30,F30,1,FERIADOS!$A$2:$A$50)+MAX(0,NETWORKDAYS.INTL(F30+1,NOW()-1,1,FERIADOS!$A$2:$A$50))*10+MAX(0,(MIN(NOW(),INT(NOW())+18/24)-(INT(NOW())+8/24)))*24*NETWORKDAYS.INTL(NOW(),NOW(),1,FERIADOS!$A$2:$A$50))) | P30: =IF($A30="","",IF(OR(O30="",O30=0),"00h 00m",TEXT(INT(O30),"00") & "h " & TEXT(INT((O30-INT(O30))*60),"00") & "m")) | Q30: =IF($A30="","",IF(OR(O30="",O30<=4),"🔵 Até 4h",IF(O30<=8,"🟢 Entre 4h e 8h",IF(O30<=12,"🟡 Entre 8h e 12h",IF(O30<=24,"🟠 Entre 12h e 24h","🔴 Maior que 24h"))))) | R30: =IF($A30="","",IF(OR(O30="",O30<=8),"NO PRAZO","FORA DO PRAZO")) | S30: =IF($A30="","",COUNTIF($N$2:N30,$N30)) | T30: =IF($A30="","",IF($N30="SLN MA",1,IF($N30="GIGA+ MA",2,IF($N30="GIGA+ PI",3,IF($N30="SLN PA",4,IF($N30="ADX",5,6)))))) | U30: =IF($A30="","",$T30*10000+$S30) | V30: https://atrix.mobtelecom.com.br/controle/addonmodules.php?module=helpdesk#/app/ticket/5975445
